Workbook

Sheet 使用说明与来源
A1: OAPT 研究方案进度管理
A3: 用途 | B3: 管理 A/B/C 三人各 50 个工作日个人计划、总览甘特图和每周两次讨论节点。
A4: 计划来源 | B4: 仅使用四个指定 OAPT DOCX；源文索引提供块级追溯。
A5: 日期口径 | B5: D1=2026-10-19（周一）；每周五个工作日，D50=2026-12-25；周末不计入 50 日。
A6: 人员分表 | B6: A_核心算法、B_测试平台、C_基线复现分别对应 A/B/C DOCX 的 50 个逐日段落。
A7: 总览口径 | B7: 总览逐行引用人员分表；负责人 A 的第二行即 A2/D2，周目标来自人员表“本周目标”列。
A8: 状态更新 | B8: 完成任务时更新对应人员表同一工作日行：状态、完成度、实际开始/结束日期、交付/保存位置、证据/阻塞、备注。
A9: 讨论机制 | B9: 每周周三/周四二选一和周日复盘；建议日期由 D1 起点推导，固定时间与议题文件中未提供，需确认。
A10: 计划冲突 | B10: 统一方案为 13 周，A/B/C 清单为 10 周 50 个工作日，差异保留待导师确认。

Sheet A_核心算法
A1: A 工作分表与 50 工作日甘特图
A2: 计划日期按 2026-10-19（周一）起每周五个工作日计算；周末不占用 D1-D50。状态、完成度、实际日期、交付位置、证据/阻塞和备注可更新。
A3: 角色颜色 | B3: A—攻击样本生成 | V3: 46314 | W3: 46315 | X3: 46316 | Y3: 46317 | Z3: 46318 | AA3: 46321 | AB3: 46322 | AC3: 46323 | AD3: 46324 | AE3: 46325 | AF3: 46328 | AG3: 46329 | AH3: 46330 | AI3: 46331 | AJ3: 46332 | AK3: 46335 | AL3: 46336 | AM3: 46337 | AN3: 46338 | AO3: 46339 | AP3: 46342 | AQ3: 46343 | AR3: 46344 | AS3: 46345 | AT3: 46346 | AU3: 46349 | AV3: 46350 | AW3: 46351 | AX3: 46352 | AY3: 46353 | AZ3: 46356 | BA3: 46357 | BB3: 46358 | BC3: 46359 | BD3: 46360 | BE3: 46363 | BF3: 46364 | BG3: 46365 | BH3: 46366 | BI3: 46367 | BJ3: 46370 | BK3: 46371 | BL3: 46372 | BM3: 46373 | BN3: 46374 | BO3: 46377 | BP3: 46378 | BQ3: 46379 | BR3: 46380 | BS3: 46381
A4: 工作日编号 | B4: 计划开始日期 | C4: 计划结束日期 | D4: 来源块 | E4: 原文日标题 | F4: 任务名称/当天操作 | G4: 本周目标 | H4: 当天类型 | I4: 阅读/参考（原文） | J4: 开始前准备 | K4: 预期结果 | L4: 当天保存 | M4: 验收标准 | N4: 失败处理 | O4: 状态 | P4: 完成度 | Q4: 实际开始日期 | R4: 实际结束日期 | S4: 交付/保存位置 | T4: 证据/阻塞 | U4: 备注 | V4: D1 | W4: D2 | X4: D3 | Y4: D4 | Z4: D5 | AA4: D6 | AB4: D7 | AC4: D8 | AD4: D9 | AE4: D10 | AF4: D11 | AG4: D12 | AH4: D13 | AI4: D14 | AJ4: D15 | AK4: D16 | AL4: D17 | AM4: D18 | AN4: D19 | AO4: D20 | AP4: D21 | AQ4: D22 | AR4: D23 | AS4: D24 | AT4: D25 | AU4: D26 | AV4: D27 | AW4: D28 | AX4: D29 | AY4: D30 | AZ4: D31 | BA4: D32 | BB4: D33 | BC4: D34 | BD4: D35 | BE4: D36 | BF4: D37 | BG4: D38 | BH4: D39 | BI4: D40 | BJ4: D41 | BK4: D42 | BL4: D43 | BM4: D44 | BN4: D45 | BO4: D46 | BP4: D47 | BQ4: D48 | BR4: D49 | BS4: D50
A5: 1 | B5: 46314 | C5: 46314 | D5: A:block-116 | E5: 第1周 第1天 明确这个算法到底做什么 | F5: 第1周 第1天 明确这个算法到底做什么 1. 写出合法任务、测试目标、输入位置和允许观察四栏。 2. 用虚构维修通知举例说明外部文本不能代替用户授权。 3. 把算法拆成读轨迹、画步骤、换场景、逐步生成四段。 4. 写一页从原始对话到测试记录的流程说明。 | G5: 明确问题并建立微型执行器 | H5: 算法研究 | I5: AgentDojo 论文 官方代码；Automated Generation and Analysis of Attack Graphs | J5: 本计划和一个空白项目目录。 | K5: 读通知和修改预约是不同步骤，不能因为读完就当预约已改。 | L5: 说明/研究任务.md。另保存当天的实际命令和执行记录。 | M5: 每一段都有输入、输出和失败例，能用自己的话解释全流程。 | O5: 未开始 | P5: 0 | V5: =IF(AND($B5<>"",$C5<>"",V$3>=$B5,V$3<=$C5),"■","") -> ■ | W5: =IF(AND($B5<>"",$C5<>"",W$3>=$B5,W$3<=$C5),"■","") | X5: =IF(AND($B5<>"",$C5<>"",X$3>=$B5,X$3<=$C5),"■","") | Y5: =IF(AND($B5<>"",$C5<>"",Y$3>=$B5,Y$3<=$C5),"■","") | Z5: =IF(AND($B5<>"",$C5<>"",Z$3>=$B5,Z$3<=$C5),"■","") | AA5: =IF(AND($B5<>"",$C5<>"",AA$3>=$B5,AA$3<=$C5),"■","") | AB5: =IF(AND($B5<>"",$C5<>"",AB$3>=$B5,AB$3<=$C5),"■","") | AC5: =IF(AND($B5<>"",$C5<>"",AC$3>=$B5,AC$3<=$C5),"■","") | ... BS5: =IF(AND($B5<>"",$C5<>"",BS$3>=$B5,BS$3<=$C5),"■","")
A6: 2 | B6: 46315 | C6: 46315 | D6: A:block-128 | E6: 第1周 第2天 独立建好开发环境 | F6: 第1周 第2天 独立建好开发环境 1. 新建算法目录及data、src、tests、results四个子目录。 2. 安装JSON校验和测试库并保存版本。 3. 写只返回固定文本的模型替身。 4. 运行一个读取样例并写结果的小程序。 | G6: 明确问题并建立微型执行器 | H6: 算法研究 | I6: JSON Schema Draft 2020 12 | J6: 可用Python环境和模型访问配置。 | K6: 不配置模型密钥也能完成固定回复测试。 | L6: 环境/依赖.txt 和 tests/固定回复测试.py。另保存当天的实际命令和执行记录。 | M6: 新环境按说明运行成功，日志中不出现密钥。 | O6: 未开始 | P6: 0 | V6: =IF(AND($B6<>"",$C6<>"",V$3>=$B6,V$3<=$C6),"■","") | W6: =IF(AND($B6<>"",$C6<>"",W$3>=$B6,W$3<=$C6),"■","") -> ■ | X6: =IF(AND($B6<>"",$C6<>"",X$3>=$B6,X$3<=$C6),"■","") | Y6: =IF(AND($B6<>"",$C6<>"",Y$3>=$B6,Y$3<=$C6),"■","") | Z6: =IF(AND($B6<>"",$C6<>"",Z$3>=$B6,Z$3<=$C6),"■","") | AA6: =IF(AND($B6<>"",$C6<>"",AA$3>=$B6,AA$3<=$C6),"■","") | AB6: =IF(AND($B6<>"",$C6<>"",AB$3>=$B6,AB$3<=$C6),"■","") | AC6: =IF(AND($B6<>"",$C6<>"",AC$3>=$B6,AC$3<=$C6),"■","") | ... BS6: =IF(AND($B6<>"",$C6<>"",BS$3>=$B6,BS$3<=$C6),"■","")
A7: 3 | B7: 46316 | C7: 46316 | D7: A:block-140 | E7: 第1周 第3天 写清输入文件长什么样 | F7: 第1周 第3天 写清输入文件长什么样 1. 给任务、轮次、消息和工具事件设置独立编号。 2. 保存说话人、原文和缺失原因。 3. 把工具请求和真正执行分两条记录。 4. 制作正常、缺字段和编号重复三个文件。 | G7: 明确问题并建立微型执行器 | H7: 算法研究 | I7: JSON Schema Draft 2020 12；PROV O The PROV Ontology | J7: 两段自己编写的无害对话。 | K7: 模型说已修改但没有工具事件时，实际执行字段为空。 | L7: data/轨迹示例.json 和 说明/字段解释.md。另保存当天的实际命令和执行记录。 | M7: 正常文件可读，另外两个返回具体错误位置而不是崩溃。 | O7: 未开始 | P7: 0 | V7: =IF(AND($B7<>"",$C7<>"",V$3>=$B7,V$3<=$C7),"■","") | W7: =IF(AND($B7<>"",$C7<>"",W$3>=$B7,W$3<=$C7),"■","") | X7: =IF(AND($B7<>"",$C7<>"",X$3>=$B7,X$3<=$C7),"■","") -> ■ | Y7: =IF(AND($B7<>"",$C7<>"",Y$3>=$B7,Y$3<=$C7),"■","") | Z7: =IF(AND($B7<>"",$C7<>"",Z$3>=$B7,Z$3<=$C7),"■","") | AA7: =IF(AND($B7<>"",$C7<>"",AA$3>=$B7,AA$3<=$C7),"■","") | AB7: =IF(AND($B7<>"",$C7<>"",AB$3>=$B7,AB$3<=$C7),"■","") | AC7: =IF(AND($B7<>"",$C7<>"",AC$3>=$B7,AC$3<=$C7),"■","") | ... BS7: =IF(AND($B7<>"",$C7<>"",BS$3>=$B7,BS$3<=$C7),"■","")
A8: 4 | B8: 46317 | C8: 46317 | D8: A:block-152 | E8: 第1周 第4天 做一个不用等待平台的微型执行器 | F8: 第1周 第4天 做一个不用等待平台的微型执行器 1. 在内存中放一封通知、一份文件和一个预约。 2. 写读取通知、读取文件、修改预约、查看结果四个函数。 3. 所有函数只读写本地字典。 4. 每次调用都输出请求、是否执行和修改前后内容。 | G8: 明确问题并建立微型执行器 | H8: 算法研究 | I8: AgentDojo 论文 官方代码 | J8: 输入样例和固定回复模型。 | K8: 修改预约后本地预约时间变化，电脑外没有任何操作。 | L8: src/mini_executor.py。另保存当天的实际命令和执行记录。 | M8: 四个函数分别能运行，重置后恢复同一初始数据。 | O8: 未开始 | P8: 0 | V8: =IF(AND($B8<>"",$C8<>"",V$3>=$B8,V$3<=$C8),"■","") | W8: =IF(AND($B8<>"",$C8<>"",W$3>=$B8,W$3<=$C8),"■","") | X8: =IF(AND($B8<>"",$C8<>"",X$3>=$B8,X$3<=$C8),"■","") | Y8: =IF(AND($B8<>"",$C8<>"",Y$3>=$B8,Y$3<=$C8),"■","") -> ■ | Z8: =IF(AND($B8<>"",$C8<>"",Z$3>=$B8,Z$3<=$C8),"■","") | AA8: =IF(AND($B8<>"",$C8<>"",AA$3>=$B8,AA$3<=$C8),"■","") | AB8: =IF(AND($B8<>"",$C8<>"",AB$3>=$B8,AB$3<=$C8),"■","") | AC8: =IF(AND($B8<>"",$C8<>"",AC$3>=$B8,AC$3<=$C8),"■","") | ... BS8: =IF(AND($B8<>"",$C8<>"",BS$3>=$B8,BS$3<=$C8),"■","")
A9: 5 | B9: 46318 | C9: 46318 | D9: A:block-164 | E9: 第1周 第5天 检查第一周是否真正可运行 | F9: 第1周 第5天 检查第一周是否真正可运行 1. 从新目录复制项目并重新安装。 2. 逐个运行读取、修改和重置示例。 3. 故意删除一个字段观察报错。 4. 记录还不会做的操作并补最小示例。 | G9: 明确问题并建立微型执行器 | H9: 算法研究 | I9: JSON Schema Draft 2020 12 | J9: 本周程序和三个样例。 | K9: 一条命令生成包含四种事件的结果文件。 | L9: 记录/第1周自查.md。另保存当天的实际命令和执行记录。 | M9: 不需要其他人的文件即可跑完；格式不符时会停下并说明原因。 | O9: 未开始 | P9: 0 | V9: =IF(AND($B9<>"",$C9<>"",V$3>=$B9,V$3<=$C9),"■","") | W9: =IF(AND($B9<>"",$C9<>"",W$3>=$B9,W$3<=$C9),"■","") | X9: =IF(AND($B9<>"",$C9<>"",X$3>=$B9,X$3<=$C9),"■","") | Y9: =IF(AND($B9<>"",$C9<>"",Y$3>=$B9,Y$3<=$C9),"■","") | Z9: =IF(AND($B9<>"",$C9<>"",Z$3>=$B9,Z$3<=$C9),"■","") -> ■ | AA9: =IF(AND($B9<>"",$C9<>"",AA$3>=$B9,AA$3<=$C9),"■","") | AB9: =IF(AND($B9<>"",$C9<>"",AB$3>=$B9,AB$3<=$C9),"■","") | AC9: =IF(AND($B9<>"",$C9<>"",AC$3>=$B9,AC$3<=$C9),"■","") | ... BS9: =IF(AND($B9<>"",$C9<>"",BS$3>=$B9,BS$3<=$C9),"■","")
A10: 6 | B10: 46321 | C10: 46321 | D10: A:block-176 | E10: 第2周 第6天 收集历史多轮轨迹 | F10: 第2周 第6天 收集历史多轮轨迹 1. 建立来源、版本、许可、实际下载文件四列表。 2. 先查看每个来源10条。 3. 标记是否含多轮回复及工具结果。 4. 继续整理至200条候选并保留排除原因。 | G10: 收集真实轨迹并建立个人标注说明 | H10: 算法研究 | I10: STAC 论文 官方代码；AgentLAB 论文 官方代码 | J10: 公开论文及可下载文件。 | K10: 200条候选中可能只有部分能建图，两个数量分开写。 | L10: data/历史来源清单.csv。另保存当天的实际命令和执行记录。 | M10: 所有记录能找到原文件；没有用自编对话冒充公开轨迹。 | O10: 未开始 | P10: 0 | V10: =IF(AND($B10<>"",$C10<>"",V$3>=$B10,V$3<=$C10),"■","") | W10: =IF(AND($B10<>"",$C10<>"",W$3>=$B10,W$3<=$C10),"■","") | X10: =IF(AND($B10<>"",$C10<>"",X$3>=$B10,X$3<=$C10),"■","") | Y10: =IF(AND($B10<>"",$C10<>"",Y$3>=$B10,Y$3<=$C10),"■","") | Z10: =IF(AND($B10<>"",$C10<>"",Z$3>=$B10,Z$3<=$C10),"■","") | AA10: =IF(AND($B10<>"",$C10<>"",AA$3>=$B10,AA$3<=$C10),"■","") -> ■ | AB10: =IF(AND($B10<>"",$C10<>"",AB$3>=$B10,AB$3<=$C10),"■","") | AC10: =IF(AND($B10<>"",$C10<>"",AC$3>=$B10,AC$3<=$C10),"■","") | ... BS10: =IF(AND($B10<>"",$C10<>"",BS$3>=$B10,BS$3<=$C10),"■","")
A11: 7 | B11: 46322 | C11: 46322 | D11: A:block-188 | E11: 第2周 第7天 筛出真正能够使用的轨迹 | F11: 第2周 第7天 筛出真正能够使用的轨迹 1. 排除重复、只有单句和缺少回复的记录。 2. 按原案例及改写变体设置同一组号。 3. 统计候选到可建图的各步数量。 4. 把不完整但仍有价值的记录另存。 | G11: 收集真实轨迹并建立个人标注说明 | H11: 算法研究 | I11: PROV O The PROV Ontology | J11: 候选清单。 | K11: 一条原始案例的三个改写只有一个来源组。 | L11: data/筛选结果.csv。另保存当天的实际命令和执行记录。 | M11: 每个排除有理由，组号无遗漏，计数前后能对上。 | O11: 未开始 | P11: 0 | V11: =IF(AND($B11<>"",$C11<>"",V$3>=$B11,V$3<=$C11),"■","") | W11: =IF(AND($B11<>"",$C11<>"",W$3>=$B11,W$3<=$C11),"■","") | X11: =IF(AND($B11<>"",$C11<>"",X$3>=$B11,X$3<=$C11),"■","") | Y11: =IF(AND($B11<>"",$C11<>"",Y$3>=$B11,Y$3<=$C11),"■","") | Z11: =IF(AND($B11<>"",$C11<>"",Z$3>=$B11,Z$3<=$C11),"■","") | AA11: =IF(AND($B11<>"",$C11<>"",AA$3>=$B11,AA$3<=$C11),"■","") | AB11: =IF(AND($B11<>"",$C11<>"",AB$3>=$B11,AB$3<=$C11),"■","") -> ■ | AC11: =IF(AND($B11<>"",$C11<>"",AC$3>=$B11,AC$3<=$C11),"■","") | ... BS11: =IF(AND($B11<>"",$C11<>"",BS$3>=$B11,BS$3<=$C11),"■","")
A12: 8 | B12: 46323 | C12: 46323 | D12: A:block-200 | E12: 第2周 第8天 自己先画十条示范步骤图 | F12: 第2周 第8天 自己先画十条示范步骤图 1. 逐轮写这一轮发生了什么。 2. 只在目标或工具效果改变时另起一步。 3. 把每一步对应原消息编号。 4. 分别画先后关系和有证据的依赖关系。 | G12: 收集真实轨迹并建立个人标注说明 | H12: 算法研究 | I12: Automated Generation and Analysis of Attack Graphs；PROV O The PROV Ontology | J12: 10条保留轨迹。 | K12: 先读文件再发消息只有先后关系，未必证明依赖。 | L12: data/人工示范图.jsonl。另保存当天的实际命令和执行记录。 | M12: 图上每一步能回查原文，没有证据的关系写尚不能确定。 | O12: 未开始 | P12: 0 | V12: =IF(AND($B12<>"",$C12<>"",V$3>=$B12,V$3<=$C12),"■","") | W12: =IF(AND($B12<>"",$C12<>"",W$3>=$B12,W$3<=$C12),"■","") | X12: =IF(AND($B12<>"",$C12<>"",X$3>=$B12,X$3<=$C12),"■","") | Y12: =IF(AND($B12<>"",$C12<>"",Y$3>=$B12,Y$3<=$C12),"■","") | Z12: =IF(AND($B12<>"",$C12<>"",Z$3>=$B12,Z$3<=$C12),"■","") | AA12: =IF(AND($B12<>"",$C12<>"",AA$3>=$B12,AA$3<=$C12),"■","") | AB12: =IF(AND($B12<>"",$C12<>"",AB$3>=$B12,AB$3<=$C12),"■","") | AC12: =IF(AND($B12<>"",$C12<>"",AC$3>=$B12,AC$3<=$C12),"■","") -> ■ | ... BS12: =IF(AND($B12<>"",$C12<>"",BS$3>=$B12,BS$3<=$C12),"■","")
A13: 9 | B13: 46324 | C13: 46324 | D13: A:block-212 | E13: 第2周 第9天 编写容易照着用的标注说明 | F13: 第2周 第9天 编写容易照着用的标注说明 1. 解释什么时候划分新步骤。 2. 给先后、依赖、未知各写两个例子。 3. 写缺少工具结果时如何处理。 4. 隔一天重新标五条并记录自己的不一致。 | G13: 收集真实轨迹并建立个人标注说明 | H13: 算法研究 | I13: Automated Generation and Analysis of Attack Graphs | J13: 十条示范图。 | K13: 自查发现两种划分不同，说明中补上边界规则。 | L13: 说明/如何划分步骤.md。另保存当天的实际命令和执行记录。 | M13: 只有单人自查就如实记录，不填写双人一致性数字。 | O13: 未开始 | P13: 0 | V13: =IF(AND($B13<>"",$C13<>"",V$3>=$B13,V$3<=$C13),"■","") | W13: =IF(AND($B13<>"",$C13<>"",W$3>=$B13,W$3<=$C13),"■","") | X13: =IF(AND($B13<>"",$C13<>"",X$3>=$B13,X$3<=$C13),"■","") | Y13: =IF(AND($B13<>"",$C13<>"",Y$3>=$B13,Y$3<=$C13),"■","") | Z13: =IF(AND($B13<>"",$C13<>"",Z$3>=$B13,Z$3<=$C13),"■","") | AA13: =IF(AND($B13<>"",$C13<>"",AA$3>=$B13,AA$3<=$C13),"■","") | AB13: =IF(AND($B13<>"",$C13<>"",AB$3>=$B13,AB$3<=$C13),"■","") | AC13: =IF(AND($B13<>"",$C13<>"",AC$3>=$B13,AC$3<=$C13),"■","") | ... BS13: =IF(AND($B13<>"",$C13<>"",BS$3>=$B13,BS$3<=$C13),"■","")
A14: 10 | B14: 46325 | C14: 46325 | D14: A:block-224 | E14: 第2周 第10天 冻结可用数据和开发样本 | F14: 第2周 第10天 冻结可用数据和开发样本 1. 把同一来源组整体放入开发或留出文件。 2. 先选20条开发用轨迹。 3. 保存其余留出数据不用于改提示。 4. 记录实际数量不足时能研究什么。 | G14: 收集真实轨迹并建立个人标注说明 | H14: 算法研究 | I14: On Over fitting in Model Selection and Subsequent Selection Bias in Performance Evaluation | J14: 筛选结果与标注说明。 | K14: 开发集和留出集没有同一原始案例的变体。 | L14: data/开发集.jsonl 和 data/留出集.jsonl。另保存当天的实际命令和执行记录。 | M14: 两文件组号交集为空；不足200条合格轨迹时报告真实缺口。 | O14: 未开始 | P14: 0 | V14: =IF(AND($B14<>"",$C14<>"",V$3>=$B14,V$3<=$C14),"■","") | W14: =IF(AND($B14<>"",$C14<>"",W$3>=$B14,W$3<=$C14),"■","") | X14: =IF(AND($B14<>"",$C14<>"",X$3>=$B14,X$3<=$C14),"■","") | Y14: =IF(AND($B14<>"",$C14<>"",Y$3>=$B14,Y$3<=$C14),"■","") | Z14: =IF(AND($B14<>"",$C14<>"",Z$3>=$B14,Z$3<=$C14),"■","") | AA14: =IF(AND($B14<>"",$C14<>"",AA$3>=$B14,AA$3<=$C14),"■","") | AB14: =IF(AND($B14<>"",$C14<>"",AB$3>=$B14,AB$3<=$C14),"■","") | AC14: =IF(AND($B14<>"",$C14<>"",AC$3>=$B14,AC$3<=$C14),"■","") | ... BS14: =IF(AND($B14<>"",$C14<>"",BS$3>=$B14,BS$3<=$C14),"■","")
A15: 11 | B15: 46328 | C15: 46328 | D15: A:block-236 | E15: 第3周 第11天 写按轮次整理对话的程序 | F15: 第3周 第11天 写按轮次整理对话的程序 1. 逐条读取消息。 2. 保持原始顺序和编号。 3. 把工具调用、返回、状态修改识别成不同事件。 4. 输出便于查看的逐轮表。 | G15: 实现步骤抽取与证据检查 | H15: 算法研究 | I15: PROV O The PROV Ontology；JSON Schema Draft 2020 12 | J15: 开发轨迹。 | K15: 同一轮的请求和返回保留两个事件编号。 | L15: src/parse_trace.py。另保存当天的实际命令和执行记录。 | M15: 20条输入不丢消息，输出可与原文逐行对应。 | O15: 未开始 | P15: 0 | V15: =IF(AND($B15<>"",$C15<>"",V$3>=$B15,V$3<=$C15),"■","") | W15: =IF(AND($B15<>"",$C15<>"",W$3>=$B15,W$3<=$C15),"■","") | X15: =IF(AND($B15<>"",$C15<>"",X$3>=$B15,X$3<=$C15),"■","") | Y15: =IF(AND($B15<>"",$C15<>"",Y$3>=$B15,Y$3<=$C15),"■","") | Z15: =IF(AND($B15<>"",$C15<>"",Z$3>=$B15,Z$3<=$C15),"■","") | AA15: =IF(AND($B15<>"",$C15<>"",AA$3>=$B15,AA$3<=$C15),"■","") | AB15: =IF(AND($B15<>"",$C15<>"",AB$3>=$B15,AB$3<=$C15),"■","") | AC15: =IF(AND($B15<>"",$C15<>"",AC$3>=$B15,AC$3<=$C15),"■","") | ... BS15: =IF(AND($B15<>"",$C15<>"",BS$3>=$B15,BS$3<=$C15),"■","")
A16: 12 | B16: 46329 | C16: 46329 | D16: A:block-248 | E16: 第3周 第12天 做最简单的规则抽取方法 | F16: 第3周 第12天 做最简单的规则抽取方法 1. 遇到工具请求建立候选步骤。 2. 把随后同编号返回绑定到该步。 3. 没有返回就标缺失。 4. 把每步的动作和对象输出成表。 | G16: 实现步骤抽取与证据检查 | H16: 算法研究 | I16: Automated Generation and Analysis of Attack Graphs | J16: 逐轮事件表。 | K16: 读取预约有返回，修改预约没有返回，两步证据等级不同。 | L16: src/rule_extract.py。另保存当天的实际命令和执行记录。 | M16: 空对话、缺返回、重复编号三个例子均能正确处理。 | O16: 未开始 | P16: 0 | V16: =IF(AND($B16<>"",$C16<>"",V$3>=$B16,V$3<=$C16),"■","") | W16: =IF(AND($B16<>"",$C16<>"",W$3>=$B16,W$3<=$C16),"■","") | X16: =IF(AND($B16<>"",$C16<>"",X$3>=$B16,X$3<=$C16),"■","") | Y16: =IF(AND($B16<>"",$C16<>"",Y$3>=$B16,Y$3<=$C16),"■","") | Z16: =IF(AND($B16<>"",$C16<>"",Z$3>=$B16,Z$3<=$C16),"■","") | AA16: =IF(AND($B16<>"",$C16<>"",AA$3>=$B16,AA$3<=$C16),"■","") | AB16: =IF(AND($B16<>"",$C16<>"",AB$3>=$B16,AB$3<=$C16),"■","") | AC16: =IF(AND($B16<>"",$C16<>"",AC$3>=$B16,AC$3<=$C16),"■","") | ... BS16: =IF(AND($B16<>"",$C16<>"",BS$3>=$B16,BS$3<=$C16),"■","")
... A54: 50 | B54: 46381 | C54: 46381 | D54: A:block-704 | E54: 第10周 第50天 完成十周独立工作 | F54: 第10周 第50天 完成十周独立工作 1. 核对50日实际记录。 2. 导出最终依赖和版本。 3. 列尚需项目负责人整合的项目。 4. 封存交付目录并结束独立开发。 | G54: 补齐回归测试并独立交付 | H54: 算法研究 | I54: On Over fitting in Model Selection and Subsequent Selection Bias in Performance Evaluation | J54: 最终代码 数据 文档与报告。 | K54: 算法包可单独运行，后续再与完整平台比较。 | L54: release/最终交付清单.md。另保存当天的实际命令和执行记录。 | M54: 核心实现完成且边界透明；不把个人验收写成整体研究已全部完成。 | O54: 未开始 | P54: 0 | V54: =IF(AND($B54<>"",$C54<>"",V$3>=$B54,V$3<=$C54),"■","") | W54: =IF(AND($B54<>"",$C54<>"",W$3>=$B54,W$3<=$C54),"■","") | X54: =IF(AND($B54<>"",$C54<>"",X$3>=$B54,X$3<=$C54),"■","") | Y54: =IF(AND($B54<>"",$C54<>"",Y$3>=$B54,Y$3<=$C54),"■","") | Z54: =IF(AND($B54<>"",$C54<>"",Z$3>=$B54,Z$3<=$C54),"■","") | AA54: =IF(AND($B54<>"",$C54<>"",AA$3>=$B54,AA$3<=$C54),"■","") | AB54: =IF(AND($B54<>"",$C54<>"",AB$3>=$B54,AB$3<=$C54),"■","") | AC54: =IF(AND($B54<>"",$C54<>"",AC$3>=$B54,AC$3<=$C54),"■","") | ... BS54: =IF(AND($B54<>"",$C54<>"",BS$3>=$B54,BS$3<=$C54),"■","") -> ■

Sheet B_测试平台
A1: B 工作分表与 50 工作日甘特图
A2: 计划日期按 2026-10-19（周一）起每周五个工作日计算；周末不占用 D1-D50。状态、完成度、实际日期、交付位置、证据/阻塞和备注可更新。
A3: 角色颜色 | B3: B—测试平台 | V3: 46314 | W3: 46315 | X3: 46316 | Y3: 46317 | Z3: 46318 | AA3: 46321 | AB3: 46322 | AC3: 46323 | AD3: 46324 | AE3: 46325 | AF3: 46328 | AG3: 46329 | AH3: 46330 | AI3: 46331 | AJ3: 46332 | AK3: 46335 | AL3: 46336 | AM3: 46337 | AN3: 46338 | AO3: 46339 | AP3: 46342 | AQ3: 46343 | AR3: 46344 | AS3: 46345 | AT3: 46346 | AU3: 46349 | AV3: 46350 | AW3: 46351 | AX3: 46352 | AY3: 46353 | AZ3: 46356 | BA3: 46357 | BB3: 46358 | BC3: 46359 | BD3: 46360 | BE3: 46363 | BF3: 46364 | BG3: 46365 | BH3: 46366 | BI3: 46367 | BJ3: 46370 | BK3: 46371 | BL3: 46372 | BM3: 46373 | BN3: 46374 | BO3: 46377 | BP3: 46378 | BQ3: 46379 | BR3: 46380 | BS3: 46381
A4: 工作日编号 | B4: 计划开始日期 | C4: 计划结束日期 | D4: 来源块 | E4: 原文日标题 | F4: 任务名称/当天操作 | G4: 本周目标 | H4: 当天类型 | I4: 阅读/参考（原文） | J4: 开始前准备 | K4: 预期结果 | L4: 当天保存 | M4: 验收标准 | N4: 失败处理 | O4: 状态 | P4: 完成度 | Q4: 实际开始日期 | R4: 实际结束日期 | S4: 交付/保存位置 | T4: 证据/阻塞 | U4: 备注 | V4: D1 | W4: D2 | X4: D3 | Y4: D4 | Z4: D5 | AA4: D6 | AB4: D7 | AC4: D8 | AD4: D9 | AE4: D10 | AF4: D11 | AG4: D12 | AH4: D13 | AI4: D14 | AJ4: D15 | AK4: D16 | AL4: D17 | AM4: D18 | AN4: D19 | AO4: D20 | AP4: D21 | AQ4: D22 | AR4: D23 | AS4: D24 | AT4: D25 | AU4: D26 | AV4: D27 | AW4: D28 | AX4: D29 | AY4: D30 | AZ4: D31 | BA4: D32 | BB4: D33 | BC4: D34 | BD4: D35 | BE4: D36 | BF4: D37 | BG4: D38 | BH4: D39 | BI4: D40 | BJ4: D41 | BK4: D42 | BL4: D43 | BM4: D44 | BN4: D45 | BO4: D46 | BP4: D47 | BQ4: D48 | BR4: D49 | BS4: D50
A5: 1 | B5: 46314 | C5: 46314 | D5: B:block-91 | E5: 第1周 第1天 先明确平台要模拟哪些事情 | F5: 第1周 第1天 先明确平台要模拟哪些事情 1. 列邮件、文件、日程、车载四个必做场景。 2. 为每个场景写合法用户任务。 3. 把读取和修改分成两类。 4. 写平台只操作合成数据的范围说明。 | G5: 安装现有基础并建立独立入口 | H5: 主要实现 | I5: AgentDojo 论文 官方代码 | J5: 本计划和空白项目目录。 | K5: 车载助手可以预约维修，但这里只改本地预约数据。 | L5: 说明/平台范围.md。另保存当天的实际命令和执行记录。 | M5: 四场景均有合法任务和不允许操作的例子，车载不是可选项。 | O5: 未开始 | P5: 0 | V5: =IF(AND($B5<>"",$C5<>"",V$3>=$B5,V$3<=$C5),"■","") -> ■ | W5: =IF(AND($B5<>"",$C5<>"",W$3>=$B5,W$3<=$C5),"■","") | X5: =IF(AND($B5<>"",$C5<>"",X$3>=$B5,X$3<=$C5),"■","") | Y5: =IF(AND($B5<>"",$C5<>"",Y$3>=$B5,Y$3<=$C5),"■","") | Z5: =IF(AND($B5<>"",$C5<>"",Z$3>=$B5,Z$3<=$C5),"■","") | AA5: =IF(AND($B5<>"",$C5<>"",AA$3>=$B5,AA$3<=$C5),"■","") | AB5: =IF(AND($B5<>"",$C5<>"",AB$3>=$B5,AB$3<=$C5),"■","") | AC5: =IF(AND($B5<>"",$C5<>"",AC$3>=$B5,AC$3<=$C5),"■","") | ... BS5: =IF(AND($B5<>"",$C5<>"",BS$3>=$B5,BS$3<=$C5),"■","")
A6: 2 | B6: 46315 | C6: 46315 | D6: B:block-103 | E6: 第1周 第2天 安装现成环境并运行最小例子 | F6: 第1周 第2天 安装现成环境并运行最小例子 1. 按官方说明安装独立环境。 2. 运行工具注册和依赖检查。 3. 先用固定回复代替真实模型。 4. 保存实际安装命令和版本。 | G6: 安装现有基础并建立独立入口 | H6: 主要实现 | I6: AgentDojo 论文 官方代码 | J6: 官方代码和可用Python环境。 | K6: 没有模型密钥时也能测试工具函数。 | L6: 环境/安装记录.md。另保存当天的实际命令和执行记录。 | M6: 从空环境重复安装成功，模型调用与工具测试分开。 | O6: 未开始 | P6: 0 | V6: =IF(AND($B6<>"",$C6<>"",V$3>=$B6,V$3<=$C6),"■","") | W6: =IF(AND($B6<>"",$C6<>"",W$3>=$B6,W$3<=$C6),"■","") -> ■ | X6: =IF(AND($B6<>"",$C6<>"",X$3>=$B6,X$3<=$C6),"■","") | Y6: =IF(AND($B6<>"",$C6<>"",Y$3>=$B6,Y$3<=$C6),"■","") | Z6: =IF(AND($B6<>"",$C6<>"",Z$3>=$B6,Z$3<=$C6),"■","") | AA6: =IF(AND($B6<>"",$C6<>"",AA$3>=$B6,AA$3<=$C6),"■","") | AB6: =IF(AND($B6<>"",$C6<>"",AB$3>=$B6,AB$3<=$C6),"■","") | AC6: =IF(AND($B6<>"",$C6<>"",AC$3>=$B6,AC$3<=$C6),"■","") | ... BS6: =IF(AND($B6<>"",$C6<>"",BS$3>=$B6,BS$3<=$C6),"■","")
A7: 3 | B7: 46316 | C7: 46316 | D7: B:block-115 | E7: 第1周 第3天 设计一个通用运行入口 | F7: 第1周 第3天 设计一个通用运行入口 1. 规定任务说明、用户身份、初始数据和权限四部分。 2. 写读取任务文件的程序。 3. 把工具调用传给执行函数。 4. 保存每轮输入与输出。 | G7: 安装现有基础并建立独立入口 | H7: 主要实现 | I7: JSON Schema Draft 2020 12 | J7: 两个手工任务文件。 | K7: 换任务文件即可换场景，无需改主程序。 | L7: src/run_task.py 和 data/任务示例.json。另保存当天的实际命令和执行记录。 | M7: 两个任务都可运行，错误参数能返回具体解释。 | O7: 未开始 | P7: 0 | V7: =IF(AND($B7<>"",$C7<>"",V$3>=$B7,V$3<=$C7),"■","") | W7: =IF(AND($B7<>"",$C7<>"",W$3>=$B7,W$3<=$C7),"■","") | X7: =IF(AND($B7<>"",$C7<>"",X$3>=$B7,X$3<=$C7),"■","") -> ■ | Y7: =IF(AND($B7<>"",$C7<>"",Y$3>=$B7,Y$3<=$C7),"■","") | Z7: =IF(AND($B7<>"",$C7<>"",Z$3>=$B7,Z$3<=$C7),"■","") | AA7: =IF(AND($B7<>"",$C7<>"",AA$3>=$B7,AA$3<=$C7),"■","") | AB7: =IF(AND($B7<>"",$C7<>"",AB$3>=$B7,AB$3<=$C7),"■","") | AC7: =IF(AND($B7<>"",$C7<>"",AC$3>=$B7,AC$3<=$C7),"■","") | ... BS7: =IF(AND($B7<>"",$C7<>"",BS$3>=$B7,BS$3<=$C7),"■","")
A8: 4 | B8: 46317 | C8: 46317 | D8: B:block-127 | E8: 第1周 第4天 个人检查第一版入口 | F8: 第1周 第4天 个人检查第一版入口 1. 从终端依次加载两份任务。 2. 检查任务编号不会混用。 3. 故意删除身份字段。 4. 把运行和错误处理写进个人自查表。 | G8: 安装现有基础并建立独立入口 | H8: 个人检查 | I8: JSON Schema Draft 2020 12 | J8: 本周程序与任务示例。 | K8: 缺身份时平台停止而非默认按管理员执行。 | L8: 记录/第1周检查.md。另保存当天的实际命令和执行记录。 | M8: 无需其他人的算法或基线就能启动。 | O8: 未开始 | P8: 0 | V8: =IF(AND($B8<>"",$C8<>"",V$3>=$B8,V$3<=$C8),"■","") | W8: =IF(AND($B8<>"",$C8<>"",W$3>=$B8,W$3<=$C8),"■","") | X8: =IF(AND($B8<>"",$C8<>"",X$3>=$B8,X$3<=$C8),"■","") | Y8: =IF(AND($B8<>"",$C8<>"",Y$3>=$B8,Y$3<=$C8),"■","") -> ■ | Z8: =IF(AND($B8<>"",$C8<>"",Z$3>=$B8,Z$3<=$C8),"■","") | AA8: =IF(AND($B8<>"",$C8<>"",AA$3>=$B8,AA$3<=$C8),"■","") | AB8: =IF(AND($B8<>"",$C8<>"",AB$3>=$B8,AB$3<=$C8),"■","") | AC8: =IF(AND($B8<>"",$C8<>"",AC$3>=$B8,AC$3<=$C8),"■","") | ... BS8: =IF(AND($B8<>"",$C8<>"",BS$3>=$B8,BS$3<=$C8),"■","")
A9: 5 | B9: 46318 | C9: 46318 | D9: B:block-139 | E9: 第1周 第5天 安装和问题修复机动 | F9: 第1周 第5天 安装和问题修复机动 1. 只修复安装、读取文件和工具注册问题。 2. 把错误截图或日志保存。 3. 更新已解决状态。 4. 没有阻塞时停止开发保留休整。 | G9: 安装现有基础并建立独立入口 | H9: 机动与整理 | I9: AgentDojo 论文 官方代码 | J9: 本周故障清单。 | K9: 问题清单为空即可结束当天工作。 | L9: 记录/第1周机动.md。另保存当天的实际命令和执行记录。 | M9: 不额外增加功能，不把安装故障记为安全违规。 | O9: 未开始 | P9: 0 | V9: =IF(AND($B9<>"",$C9<>"",V$3>=$B9,V$3<=$C9),"■","") | W9: =IF(AND($B9<>"",$C9<>"",W$3>=$B9,W$3<=$C9),"■","") | X9: =IF(AND($B9<>"",$C9<>"",X$3>=$B9,X$3<=$C9),"■","") | Y9: =IF(AND($B9<>"",$C9<>"",Y$3>=$B9,Y$3<=$C9),"■","") | Z9: =IF(AND($B9<>"",$C9<>"",Z$3>=$B9,Z$3<=$C9),"■","") -> ■ | AA9: =IF(AND($B9<>"",$C9<>"",AA$3>=$B9,AA$3<=$C9),"■","") | AB9: =IF(AND($B9<>"",$C9<>"",AB$3>=$B9,AB$3<=$C9),"■","") | AC9: =IF(AND($B9<>"",$C9<>"",AC$3>=$B9,AC$3<=$C9),"■","") | ... BS9: =IF(AND($B9<>"",$C9<>"",BS$3>=$B9,BS$3<=$C9),"■","")
A10: 6 | B10: 46321 | C10: 46321 | D10: B:block-151 | E10: 第2周 第6天 建立邮件场景的初始数据 | F10: 第2周 第6天 建立邮件场景的初始数据 1. 创建收件箱、发件箱和草稿箱。 2. 每封邮件加所有者及邮件编号。 3. 加入一封普通通知和一封维修通知。 4. 写恢复初始数据的函数。 | G10: 完成邮件场景 | H10: 主要实现 | I10: AgentDojo 论文 官方代码 | J10: 两名虚构用户和邮件工具说明。 | K10: 每次重置都回到相同三封合成邮件。 | L10: data/email/ 和 src/email_state.py。另保存当天的实际命令和执行记录。 | M10: 用户不会读到另一个收件箱，重置结果一致。 | O10: 未开始 | P10: 0 | V10: =IF(AND($B10<>"",$C10<>"",V$3>=$B10,V$3<=$C10),"■","") | W10: =IF(AND($B10<>"",$C10<>"",W$3>=$B10,W$3<=$C10),"■","") | X10: =IF(AND($B10<>"",$C10<>"",X$3>=$B10,X$3<=$C10),"■","") | Y10: =IF(AND($B10<>"",$C10<>"",Y$3>=$B10,Y$3<=$C10),"■","") | Z10: =IF(AND($B10<>"",$C10<>"",Z$3>=$B10,Z$3<=$C10),"■","") | AA10: =IF(AND($B10<>"",$C10<>"",AA$3>=$B10,AA$3<=$C10),"■","") -> ■ | AB10: =IF(AND($B10<>"",$C10<>"",AB$3>=$B10,AB$3<=$C10),"■","") | AC10: =IF(AND($B10<>"",$C10<>"",AC$3>=$B10,AC$3<=$C10),"■","") | ... BS10: =IF(AND($B10<>"",$C10<>"",BS$3>=$B10,BS$3<=$C10),"■","")
A11: 7 | B11: 46322 | C11: 46322 | D11: B:block-163 | E11: 第2周 第7天 实现邮件读取和模拟发送 | F11: 第2周 第7天 实现邮件读取和模拟发送 1. 写搜索、读邮件和发送三个函数。 2. 发送只写本地发件箱。 3. 保存调用者、收件人和正文参数。 4. 给无权限访问返回拒绝理由。 | G11: 完成邮件场景 | H11: 主要实现 | I11: AgentDojo 论文 官方代码 | J11: 邮件初始数据。 | K11: 发送后本地发件箱增加一条，外部不产生邮件。 | L11: src/email_tools.py。另保存当天的实际命令和执行记录。 | M11: 合法三工具可用，无权读邮件不会返回正文。 | O11: 未开始 | P11: 0 | V11: =IF(AND($B11<>"",$C11<>"",V$3>=$B11,V$3<=$C11),"■","") | W11: =IF(AND($B11<>"",$C11<>"",W$3>=$B11,W$3<=$C11),"■","") | X11: =IF(AND($B11<>"",$C11<>"",X$3>=$B11,X$3<=$C11),"■","") | Y11: =IF(AND($B11<>"",$C11<>"",Y$3>=$B11,Y$3<=$C11),"■","") | Z11: =IF(AND($B11<>"",$C11<>"",Z$3>=$B11,Z$3<=$C11),"■","") | AA11: =IF(AND($B11<>"",$C11<>"",AA$3>=$B11,AA$3<=$C11),"■","") | AB11: =IF(AND($B11<>"",$C11<>"",AB$3>=$B11,AB$3<=$C11),"■","") -> ■ | AC11: =IF(AND($B11<>"",$C11<>"",AC$3>=$B11,AC$3<=$C11),"■","") | ... BS11: =IF(AND($B11<>"",$C11<>"",BS$3>=$B11,BS$3<=$C11),"■","")
A12: 8 | B12: 46323 | C12: 46323 | D12: B:block-175 | E12: 第2周 第8天 做邮件场景的可运行助手 | F12: 第2周 第8天 做邮件场景的可运行助手 1. 把工具列表交给模型或固定脚本。 2. 限制每个任务最多五轮。 3. 将工具返回再送入下一轮。 4. 保存最终任务结果和全部事件。 | G12: 完成邮件场景 | H12: 主要实现 | I12: AgentDojo 论文 官方代码 | J12: 邮件工具和通用入口。 | K12: 助手能够查到通知并生成草稿。 | L12: configs/email.json 和 示例/邮件任务/。另保存当天的实际命令和执行记录。 | M12: 固定脚本模式和模型模式共用工具，五轮内必定停止。 | O12: 未开始 | P12: 0 | V12: =IF(AND($B12<>"",$C12<>"",V$3>=$B12,V$3<=$C12),"■","") | W12: =IF(AND($B12<>"",$C12<>"",W$3>=$B12,W$3<=$C12),"■","") | X12: =IF(AND($B12<>"",$C12<>"",X$3>=$B12,X$3<=$C12),"■","") | Y12: =IF(AND($B12<>"",$C12<>"",Y$3>=$B12,Y$3<=$C12),"■","") | Z12: =IF(AND($B12<>"",$C12<>"",Z$3>=$B12,Z$3<=$C12),"■","") | AA12: =IF(AND($B12<>"",$C12<>"",AA$3>=$B12,AA$3<=$C12),"■","") | AB12: =IF(AND($B12<>"",$C12<>"",AB$3>=$B12,AB$3<=$C12),"■","") | AC12: =IF(AND($B12<>"",$C12<>"",AC$3>=$B12,AC$3<=$C12),"■","") -> ■ | ... BS12: =IF(AND($B12<>"",$C12<>"",BS$3>=$B12,BS$3<=$C12),"■","")
A13: 9 | B13: 46324 | C13: 46324 | D13: B:block-187 | E13: 第2周 第9天 个人复查邮件的真实效果 | F13: 第2周 第9天 个人复查邮件的真实效果 1. 核对模型说发送与实际发件箱变化。 2. 加入只口头声称已发送的例子。 3. 检查拒绝访问后未泄露正文。 4. 保存预期和实际结果。 | G13: 完成邮件场景 | H13: 个人检查 | I13: PROV O The PROV Ontology | J13: 十条邮件测试记录。 | K13: 只有模型文字已发送时，实际发送仍为否。 | L13: 记录/邮件验收.csv。另保存当天的实际命令和执行记录。 | M13: 十条记录逐一可复查，不以文字回答代替状态。 | O13: 未开始 | P13: 0 | V13: =IF(AND($B13<>"",$C13<>"",V$3>=$B13,V$3<=$C13),"■","") | W13: =IF(AND($B13<>"",$C13<>"",W$3>=$B13,W$3<=$C13),"■","") | X13: =IF(AND($B13<>"",$C13<>"",X$3>=$B13,X$3<=$C13),"■","") | Y13: =IF(AND($B13<>"",$C13<>"",Y$3>=$B13,Y$3<=$C13),"■","") | Z13: =IF(AND($B13<>"",$C13<>"",Z$3>=$B13,Z$3<=$C13),"■","") | AA13: =IF(AND($B13<>"",$C13<>"",AA$3>=$B13,AA$3<=$C13),"■","") | AB13: =IF(AND($B13<>"",$C13<>"",AB$3>=$B13,AB$3<=$C13),"■","") | AC13: =IF(AND($B13<>"",$C13<>"",AC$3>=$B13,AC$3<=$C13),"■","") | ... BS13: =IF(AND($B13<>"",$C13<>"",BS$3>=$B13,BS$3<=$C13),"■","")
A14: 10 | B14: 46325 | C14: 46325 | D14: B:block-199 | E14: 第2周 第10天 邮件阶段机动与封存 | F14: 第2周 第10天 邮件阶段机动与封存 1. 优先修复状态未重置或身份串用。 2. 重新运行受影响用例。 3. 保存稳定示例和版本。 4. 没有阻塞时保留机动时间。 | G14: 完成邮件场景 | H14: 机动与整理 | I14: On Over fitting in Model Selection and Subsequent Selection Bias in Performance Evaluation | J14: 邮件问题清单。 | K14: 邮件模块可以独立运行和重复重置。 | L14: release/邮件最小版/。另保存当天的实际命令和执行记录。 | M14: 原始失败保留，机动日不安排新场景开发。 | O14: 未开始 | P14: 0 | V14: =IF(AND($B14<>"",$C14<>"",V$3>=$B14,V$3<=$C14),"■","") | W14: =IF(AND($B14<>"",$C14<>"",W$3>=$B14,W$3<=$C14),"■","") | X14: =IF(AND($B14<>"",$C14<>"",X$3>=$B14,X$3<=$C14),"■","") | Y14: =IF(AND($B14<>"",$C14<>"",Y$3>=$B14,Y$3<=$C14),"■","") | Z14: =IF(AND($B14<>"",$C14<>"",Z$3>=$B14,Z$3<=$C14),"■","") | AA14: =IF(AND($B14<>"",$C14<>"",AA$3>=$B14,AA$3<=$C14),"■","") | AB14: =IF(AND($B14<>"",$C14<>"",AB$3>=$B14,AB$3<=$C14),"■","") | AC14: =IF(AND($B14<>"",$C14<>"",AC$3>=$B14,AC$3<=$C14),"■","") | ... BS14: =IF(AND($B14<>"",$C14<>"",BS$3>=$B14,BS$3<=$C14),"■","")
A15: 11 | B15: 46328 | C15: 46328 | D15: B:block-211 | E15: 第3周 第11天 建立文件及权限数据 | F15: 第3周 第11天 建立文件及权限数据 1. 创建公开文件、用户私有文件、共享文件各两份。 2. 记录拥有者和可读可写用户。 3. 文件正文使用虚构内容。 4. 写统一读取权限检查函数。 | G15: 完成文件和日程场景 | H15: 主要实现 | I15: AgentDojo 论文 官方代码 | J15: 文件资源设计。 | K15: 同一文件可允许读但不允许改。 | L15: data/files/ 和 src/file_permissions.py。另保存当天的实际命令和执行记录。 | M15: 六个文件权限明确，缺少规则时默认拒绝。 | O15: 未开始 | P15: 0 | V15: =IF(AND($B15<>"",$C15<>"",V$3>=$B15,V$3<=$C15),"■","") | W15: =IF(AND($B15<>"",$C15<>"",W$3>=$B15,W$3<=$C15),"■","") | X15: =IF(AND($B15<>"",$C15<>"",X$3>=$B15,X$3<=$C15),"■","") | Y15: =IF(AND($B15<>"",$C15<>"",Y$3>=$B15,Y$3<=$C15),"■","") | Z15: =IF(AND($B15<>"",$C15<>"",Z$3>=$B15,Z$3<=$C15),"■","") | AA15: =IF(AND($B15<>"",$C15<>"",AA$3>=$B15,AA$3<=$C15),"■","") | AB15: =IF(AND($B15<>"",$C15<>"",AB$3>=$B15,AB$3<=$C15),"■","") | AC15: =IF(AND($B15<>"",$C15<>"",AC$3>=$B15,AC$3<=$C15),"■","") | ... BS15: =IF(AND($B15<>"",$C15<>"",BS$3>=$B15,BS$3<=$C15),"■","")
A16: 12 | B16: 46329 | C16: 46329 | D16: B:block-223 | E16: 第3周 第12天 实现文件搜索读取和共享 | F16: 第3周 第12天 实现文件搜索读取和共享 1. 写按关键词搜索和按编号读取。 2. 写修改共享名单函数。 3. 所有修改前检查身份。 4. 保存修改前后共享名单。 | G16: 完成文件和日程场景 | H16: 主要实现 | I16: AgentDojo 论文 官方代码 | J16: 文件初始数据。 | K16: 无权共享时名单不变化。 | L16: src/file_tools.py。另保存当天的实际命令和执行记录。 | M16: 正常读取、允许共享、拒绝共享各有可运行例。 | O16: 未开始 | P16: 0 | V16: =IF(AND($B16<>"",$C16<>"",V$3>=$B16,V$3<=$C16),"■","") | W16: =IF(AND($B16<>"",$C16<>"",W$3>=$B16,W$3<=$C16),"■","") | X16: =IF(AND($B16<>"",$C16<>"",X$3>=$B16,X$3<=$C16),"■","") | Y16: =IF(AND($B16<>"",$C16<>"",Y$3>=$B16,Y$3<=$C16),"■","") | Z16: =IF(AND($B16<>"",$C16<>"",Z$3>=$B16,Z$3<=$C16),"■","") | AA16: =IF(AND($B16<>"",$C16<>"",AA$3>=$B16,AA$3<=$C16),"■","") | AB16: =IF(AND($B16<>"",$C16<>"",AB$3>=$B16,AB$3<=$C16),"■","") | AC16: =IF(AND($B16<>"",$C16<>"",AC$3>=$B16,AC$3<=$C16),"■","") | ... BS16: =IF(AND($B16<>"",$C16<>"",BS$3>=$B16,BS$3<=$C16),"■","")
... A54: 50 | B54: 46381 | C54: 46381 | D54: B:block-679 | E54: 第10周 第50天 完成十周独立交付 | F54: 第10周 第50天 完成十周独立交付 1. 打包代码和合成数据。 2. 附依赖锁及任务输入输出说明。 3. 列完成后由负责人进行的统一接入项目。 4. 封存版本并结束个人开发。 | G54: 核验车载完整性并独立交付 | H54: 机动与整理 | I54: On Over fitting in Model Selection and Subsequent Selection Bias in Performance Evaluation | J54: 平台 车载示例 文档与回归结果。 | K54: 完整平台已独立验收，后续才接测试生成算法。 | L54: release/平台最终清单.md。另保存当天的实际命令和执行记录。 | M54: 四场景均交付；没有借用尚未完成的联合实验作为验收依据。 | O54: 未开始 | P54: 0 | V54: =IF(AND($B54<>"",$C54<>"",V$3>=$B54,V$3<=$C54),"■","") | W54: =IF(AND($B54<>"",$C54<>"",W$3>=$B54,W$3<=$C54),"■","") | X54: =IF(AND($B54<>"",$C54<>"",X$3>=$B54,X$3<=$C54),"■","") | Y54: =IF(AND($B54<>"",$C54<>"",Y$3>=$B54,Y$3<=$C54),"■","") | Z54: =IF(AND($B54<>"",$C54<>"",Z$3>=$B54,Z$3<=$C54),"■","") | AA54: =IF(AND($B54<>"",$C54<>"",AA$3>=$B54,AA$3<=$C54),"■","") | AB54: =IF(AND($B54<>"",$C54<>"",AB$3>=$B54,AB$3<=$C54),"■","") | AC54: =IF(AND($B54<>"",$C54<>"",AC$3>=$B54,AC$3<=$C54),"■","") | ... BS54: =IF(AND($B54<>"",$C54<>"",BS$3>=$B54,BS$3<=$C54),"■","") -> ■

Sheet C_基线复现
A1: C 工作分表与 50 工作日甘特图
A2: 计划日期按 2026-10-19（周一）起每周五个工作日计算；周末不占用 D1-D50。状态、完成度、实际日期、交付位置、证据/阻塞和备注可更新。
A3: 角色颜色 | B3: C—基线复现 | V3: 46314 | W3: 46315 | X3: 46316 | Y3: 46317 | Z3: 46318 | AA3: 46321 | AB3: 46322 | AC3: 46323 | AD3: 46324 | AE3: 46325 | AF3: 46328 | AG3: 46329 | AH3: 46330 | AI3: 46331 | AJ3: 46332 | AK3: 46335 | AL3: 46336 | AM3: 46337 | AN3: 46338 | AO3: 46339 | AP3: 46342 | AQ3: 46343 | AR3: 46344 | AS3: 46345 | AT3: 46346 | AU3: 46349 | AV3: 46350 | AW3: 46351 | AX3: 46352 | AY3: 46353 | AZ3: 46356 | BA3: 46357 | BB3: 46358 | BC3: 46359 | BD3: 46360 | BE3: 46363 | BF3: 46364 | BG3: 46365 | BH3: 46366 | BI3: 46367 | BJ3: 46370 | BK3: 46371 | BL3: 46372 | BM3: 46373 | BN3: 46374 | BO3: 46377 | BP3: 46378 | BQ3: 46379 | BR3: 46380 | BS3: 46381
A4: 工作日编号 | B4: 计划开始日期 | C4: 计划结束日期 | D4: 来源块 | E4: 原文日标题 | F4: 任务名称/当天操作 | G4: 本周目标 | H4: 当天类型 | I4: 阅读/参考（原文） | J4: 开始前准备 | K4: 预期结果 | L4: 当天保存 | M4: 验收标准 | N4: 失败处理 | O4: 状态 | P4: 完成度 | Q4: 实际开始日期 | R4: 实际结束日期 | S4: 交付/保存位置 | T4: 证据/阻塞 | U4: 备注 | V4: D1 | W4: D2 | X4: D3 | Y4: D4 | Z4: D5 | AA4: D6 | AB4: D7 | AC4: D8 | AD4: D9 | AE4: D10 | AF4: D11 | AG4: D12 | AH4: D13 | AI4: D14 | AJ4: D15 | AK4: D16 | AL4: D17 | AM4: D18 | AN4: D19 | AO4: D20 | AP4: D21 | AQ4: D22 | AR4: D23 | AS4: D24 | AT4: D25 | AU4: D26 | AV4: D27 | AW4: D28 | AX4: D29 | AY4: D30 | AZ4: D31 | BA4: D32 | BB4: D33 | BC4: D34 | BD4: D35 | BE4: D36 | BF4: D37 | BG4: D38 | BH4: D39 | BI4: D40 | BJ4: D41 | BK4: D42 | BL4: D43 | BM4: D44 | BN4: D45 | BO4: D46 | BP4: D47 | BQ4: D48 | BR4: D49 | BS4: D50
A5: 1 | B5: 46314 | C5: 46314 | D5: C:block-106 | E5: 第1周 第1天 确认要复现的四种方法 | F5: 第1周 第1天 确认要复现的四种方法 1. 建立方法名、解决问题、输入、输出四列表。 2. 将STAC和AutoDojo列工具型Agent主要对照。 3. 将GAP和RACE列图共享及多轮控制机制对照。 4. 写原生评测与以后平台适配分开。 | G5: 确认四方法及建立独立环境 | H5: 主要实现 | I5: STAC 论文 官方代码；AutoDojo 论文 官方代码；GAP 论文；RACE 论文 官方代码 | J5: 四篇论文及其链接。 | K5: 四种方法都列入必做，评价目标不同。 | L5: 说明/四方法复现范围.md。另保存当天的实际命令和执行记录。 | M5: 没有只因任务不完全一样就省略GAP和RACE。 | O5: 未开始 | P5: 0 | V5: =IF(AND($B5<>"",$C5<>"",V$3>=$B5,V$3<=$C5),"■","") -> ■ | W5: =IF(AND($B5<>"",$C5<>"",W$3>=$B5,W$3<=$C5),"■","") | X5: =IF(AND($B5<>"",$C5<>"",X$3>=$B5,X$3<=$C5),"■","") | Y5: =IF(AND($B5<>"",$C5<>"",Y$3>=$B5,Y$3<=$C5),"■","") | Z5: =IF(AND($B5<>"",$C5<>"",Z$3>=$B5,Z$3<=$C5),"■","") | AA5: =IF(AND($B5<>"",$C5<>"",AA$3>=$B5,AA$3<=$C5),"■","") | AB5: =IF(AND($B5<>"",$C5<>"",AB$3>=$B5,AB$3<=$C5),"■","") | AC5: =IF(AND($B5<>"",$C5<>"",AC$3>=$B5,AC$3<=$C5),"■","") | ... BS5: =IF(AND($B5<>"",$C5<>"",BS$3>=$B5,BS$3<=$C5),"■","")
A6: 2 | B6: 46315 | C6: 46315 | D6: C:block-118 | E6: 第1周 第2天 核对代码和计算资源 | F6: 第1周 第2天 核对代码和计算资源 1. 记录仓库地址、实际版本和依赖。 2. 逐个检查入口脚本是否存在。 3. 估算GPU、模型访问和调用费用。 4. 给源码缺失模块标需要按论文补写。 | G6: 确认四方法及建立独立环境 | H6: 主要实现 | I6: STAC 论文 官方代码；AutoDojo 论文 官方代码；RACE 论文 官方代码 | J6: 官方仓库与论文。 | K6: RACE部分代码未公开时仍有明确补写计划。 | L6: 记录/代码可获得性.csv。另保存当天的实际命令和执行记录。 | M6: 仓库存在不等于整套可运行，每个模块有核对状态。 | O6: 未开始 | P6: 0 | V6: =IF(AND($B6<>"",$C6<>"",V$3>=$B6,V$3<=$C6),"■","") | W6: =IF(AND($B6<>"",$C6<>"",W$3>=$B6,W$3<=$C6),"■","") -> ■ | X6: =IF(AND($B6<>"",$C6<>"",X$3>=$B6,X$3<=$C6),"■","") | Y6: =IF(AND($B6<>"",$C6<>"",Y$3>=$B6,Y$3<=$C6),"■","") | Z6: =IF(AND($B6<>"",$C6<>"",Z$3>=$B6,Z$3<=$C6),"■","") | AA6: =IF(AND($B6<>"",$C6<>"",AA$3>=$B6,AA$3<=$C6),"■","") | AB6: =IF(AND($B6<>"",$C6<>"",AB$3>=$B6,AB$3<=$C6),"■","") | AC6: =IF(AND($B6<>"",$C6<>"",AC$3>=$B6,AC$3<=$C6),"■","") | ... BS6: =IF(AND($B6<>"",$C6<>"",BS$3>=$B6,BS$3<=$C6),"■","")
A7: 3 | B7: 46316 | C7: 46316 | D7: C:block-130 | E7: 第1周 第3天 建立四个互不冲突的环境 | F7: 第1周 第3天 建立四个互不冲突的环境 1. 每种方法单建虚拟环境或容器。 2. 安装各自依赖。 3. 记录运行解释器路径。 4. 先做导入和帮助信息检查。 | G7: 确认四方法及建立独立环境 | H7: 主要实现 | I7: JSON Schema Draft 2020 12 | J7: 四方法依赖清单。 | K7: AutoDojo分支不会覆盖另一个环境中的AgentDojo。 | L7: 环境/四方法安装.md。另保存当天的实际命令和执行记录。 | M7: 能区分每种方法实际使用的包与解释器。 | O7: 未开始 | P7: 0 | V7: =IF(AND($B7<>"",$C7<>"",V$3>=$B7,V$3<=$C7),"■","") | W7: =IF(AND($B7<>"",$C7<>"",W$3>=$B7,W$3<=$C7),"■","") | X7: =IF(AND($B7<>"",$C7<>"",X$3>=$B7,X$3<=$C7),"■","") -> ■ | Y7: =IF(AND($B7<>"",$C7<>"",Y$3>=$B7,Y$3<=$C7),"■","") | Z7: =IF(AND($B7<>"",$C7<>"",Z$3>=$B7,Z$3<=$C7),"■","") | AA7: =IF(AND($B7<>"",$C7<>"",AA$3>=$B7,AA$3<=$C7),"■","") | AB7: =IF(AND($B7<>"",$C7<>"",AB$3>=$B7,AB$3<=$C7),"■","") | AC7: =IF(AND($B7<>"",$C7<>"",AC$3>=$B7,AC$3<=$C7),"■","") | ... BS7: =IF(AND($B7<>"",$C7<>"",BS$3>=$B7,BS$3<=$C7),"■","")
A8: 4 | B8: 46317 | C8: 46317 | D8: C:block-142 | E8: 第1周 第4天 个人复查数据和标签含义 | F8: 第1周 第4天 个人复查数据和标签含义 1. 分别写原论文成功是什么意思。 2. 区分不安全文字与真实工具违规。 3. 写不可比任务如何单列。 4. 建立原始样例、运行结果、改动记录目录。 | G8: 确认四方法及建立独立环境 | H8: 个人检查 | I8: On Over fitting in Model Selection and Subsequent Selection Bias in Performance Evaluation | J8: 论文数据说明。 | K8: GAP文本成功不能直接写成车辆权限违规。 | L8: 说明/成功定义与比较边界.md。另保存当天的实际命令和执行记录。 | M8: 四方法各有独立判据，尚无统一平台结果时不混算ASR。 | O8: 未开始 | P8: 0 | V8: =IF(AND($B8<>"",$C8<>"",V$3>=$B8,V$3<=$C8),"■","") | W8: =IF(AND($B8<>"",$C8<>"",W$3>=$B8,W$3<=$C8),"■","") | X8: =IF(AND($B8<>"",$C8<>"",X$3>=$B8,X$3<=$C8),"■","") | Y8: =IF(AND($B8<>"",$C8<>"",Y$3>=$B8,Y$3<=$C8),"■","") -> ■ | Z8: =IF(AND($B8<>"",$C8<>"",Z$3>=$B8,Z$3<=$C8),"■","") | AA8: =IF(AND($B8<>"",$C8<>"",AA$3>=$B8,AA$3<=$C8),"■","") | AB8: =IF(AND($B8<>"",$C8<>"",AB$3>=$B8,AB$3<=$C8),"■","") | AC8: =IF(AND($B8<>"",$C8<>"",AC$3>=$B8,AC$3<=$C8),"■","") | ... BS8: =IF(AND($B8<>"",$C8<>"",BS$3>=$B8,BS$3<=$C8),"■","")
A9: 5 | B9: 46318 | C9: 46318 | D9: C:block-154 | E9: 第1周 第5天 安装及资料收集机动 | F9: 第1周 第5天 安装及资料收集机动 1. 优先处理入口或依赖缺失。 2. 保存准确错误。 3. 核对GAP是否能找到作者确认的代码。 4. 无阻塞时只更新状态后休整。 | G9: 确认四方法及建立独立环境 | H9: 机动与整理 | I9: STAC 论文 官方代码；AutoDojo 论文 官方代码；GAP 论文；RACE 论文 官方代码 | J9: 本周阻塞清单。 | K9: 未核实的第三方仓库不标官方实现。 | L9: 记录/第1周机动.md。另保存当天的实际命令和执行记录。 | M9: 不靠猜测代码地址或声称下载成功完成验收。 | O9: 未开始 | P9: 0 | V9: =IF(AND($B9<>"",$C9<>"",V$3>=$B9,V$3<=$C9),"■","") | W9: =IF(AND($B9<>"",$C9<>"",W$3>=$B9,W$3<=$C9),"■","") | X9: =IF(AND($B9<>"",$C9<>"",X$3>=$B9,X$3<=$C9),"■","") | Y9: =IF(AND($B9<>"",$C9<>"",Y$3>=$B9,Y$3<=$C9),"■","") | Z9: =IF(AND($B9<>"",$C9<>"",Z$3>=$B9,Z$3<=$C9),"■","") -> ■ | AA9: =IF(AND($B9<>"",$C9<>"",AA$3>=$B9,AA$3<=$C9),"■","") | AB9: =IF(AND($B9<>"",$C9<>"",AB$3>=$B9,AB$3<=$C9),"■","") | AC9: =IF(AND($B9<>"",$C9<>"",AC$3>=$B9,AC$3<=$C9),"■","") | ... BS9: =IF(AND($B9<>"",$C9<>"",BS$3>=$B9,BS$3<=$C9),"■","")
A10: 6 | B10: 46321 | C10: 46321 | D10: C:block-166 | E10: 第2周 第6天 理解STAC的四段流程 | F10: 第2周 第6天 理解STAC的四段流程 1. 把候选工具链、执行验证、对话生成、目标执行四段写成表。 2. 给每段列输入和输出文件。 3. 核对源码入口和帮助。 4. 标出哪些需要GPU或模型访问。 | G10: 运行STAC原生评估 | H10: 主要实现 | I10: STAC 论文 官方代码 | J10: 论文方法和官方源代码。 | K10: 运行预生成数据只覆盖评估，不覆盖新生成。 | L10: 说明/STAC流程表.md。另保存当天的实际命令和执行记录。 | M10: 每段可定位真实文件，未运行状态清楚。 | O10: 未开始 | P10: 0 | V10: =IF(AND($B10<>"",$C10<>"",V$3>=$B10,V$3<=$C10),"■","") | W10: =IF(AND($B10<>"",$C10<>"",W$3>=$B10,W$3<=$C10),"■","") | X10: =IF(AND($B10<>"",$C10<>"",X$3>=$B10,X$3<=$C10),"■","") | Y10: =IF(AND($B10<>"",$C10<>"",Y$3>=$B10,Y$3<=$C10),"■","") | Z10: =IF(AND($B10<>"",$C10<>"",Z$3>=$B10,Z$3<=$C10),"■","") | AA10: =IF(AND($B10<>"",$C10<>"",AA$3>=$B10,AA$3<=$C10),"■","") -> ■ | AB10: =IF(AND($B10<>"",$C10<>"",AB$3>=$B10,AB$3<=$C10),"■","") | AC10: =IF(AND($B10<>"",$C10<>"",AC$3>=$B10,AC$3<=$C10),"■","") | ... BS10: =IF(AND($B10<>"",$C10<>"",BS$3>=$B10,BS$3<=$C10),"■","")
A11: 7 | B11: 46322 | C11: 46322 | D11: C:block-178 | E11: 第2周 第7天 运行STAC最小原生评估 | F11: 第2周 第7天 运行STAC最小原生评估 1. 取一至两个原生合成案例。 2. 先检查环境工具能初始化。 3. 按实际帮助选择模型与输出目录。 4. 运行后保存全部原始日志。 | G11: 运行STAC原生评估 | H11: 主要实现 | I11: STAC 论文 官方代码 | J11: 官方预生成样例与环境。 | K11: 得到一次完整的目标执行记录而非只有终端截图。 | L11: results/stac/原生小样例/。另保存当天的实际命令和执行记录。 | M11: 每例有初始环境、输入和终态；失败也保留。 | O11: 未开始 | P11: 0 | V11: =IF(AND($B11<>"",$C11<>"",V$3>=$B11,V$3<=$C11),"■","") | W11: =IF(AND($B11<>"",$C11<>"",W$3>=$B11,W$3<=$C11),"■","") | X11: =IF(AND($B11<>"",$C11<>"",X$3>=$B11,X$3<=$C11),"■","") | Y11: =IF(AND($B11<>"",$C11<>"",Y$3>=$B11,Y$3<=$C11),"■","") | Z11: =IF(AND($B11<>"",$C11<>"",Z$3>=$B11,Z$3<=$C11),"■","") | AA11: =IF(AND($B11<>"",$C11<>"",AA$3>=$B11,AA$3<=$C11),"■","") | AB11: =IF(AND($B11<>"",$C11<>"",AB$3>=$B11,AB$3<=$C11),"■","") -> ■ | AC11: =IF(AND($B11<>"",$C11<>"",AC$3>=$B11,AC$3<=$C11),"■","") | ... BS11: =IF(AND($B11<>"",$C11<>"",BS$3>=$B11,BS$3<=$C11),"■","")
A12: 8 | B12: 46323 | C12: 46323 | D12: C:block-190 | E12: 第2周 第8天 核对STAC评估结果是否有依据 | F12: 第2周 第8天 核对STAC评估结果是否有依据 1. 逐轮整理调用和返回。 2. 检查原Judge判断用了什么。 3. 能取状态时再比实际效果。 4. 保存原生判据与证据核验两列。 | G12: 运行STAC原生评估 | H12: 主要实现 | I12: STAC 论文 官方代码；PROV O The PROV Ontology | J12: 原生评估日志。 | K12: 原Judge说成功但无工具证据时，两列不能强行一致。 | L12: results/stac/结果核对.csv。另保存当天的实际命令和执行记录。 | M12: 不以模型裁判替代确定性工具事实，缺证据标清。 | O12: 未开始 | P12: 0 | V12: =IF(AND($B12<>"",$C12<>"",V$3>=$B12,V$3<=$C12),"■","") | W12: =IF(AND($B12<>"",$C12<>"",W$3>=$B12,W$3<=$C12),"■","") | X12: =IF(AND($B12<>"",$C12<>"",X$3>=$B12,X$3<=$C12),"■","") | Y12: =IF(AND($B12<>"",$C12<>"",Y$3>=$B12,Y$3<=$C12),"■","") | Z12: =IF(AND($B12<>"",$C12<>"",Z$3>=$B12,Z$3<=$C12),"■","") | AA12: =IF(AND($B12<>"",$C12<>"",AA$3>=$B12,AA$3<=$C12),"■","") | AB12: =IF(AND($B12<>"",$C12<>"",AB$3>=$B12,AB$3<=$C12),"■","") | AC12: =IF(AND($B12<>"",$C12<>"",AC$3>=$B12,AC$3<=$C12),"■","") -> ■ | ... BS12: =IF(AND($B12<>"",$C12<>"",BS$3>=$B12,BS$3<=$C12),"■","")
A13: 9 | B13: 46324 | C13: 46324 | D13: C:block-202 | E13: 第2周 第9天 个人复查STAC评估能重复运行 | F13: 第2周 第9天 个人复查STAC评估能重复运行 1. 从同初始环境重跑。 2. 检查输出没有覆盖旧记录。 3. 比较工具序列和结果。 4. 写每次差异及成本。 | G13: 运行STAC原生评估 | H13: 个人检查 | I13: STAC 论文 官方代码 | J13: 已通过的小样例。 | K13: 两次模型运行可能不同，日志各自完整。 | L13: 记录/STAC原生评估复查.md。另保存当天的实际命令和执行记录。 | M13: 能够说明已复现的是哪个阶段，不冒称完整流水线。 | O13: 未开始 | P13: 0 | V13: =IF(AND($B13<>"",$C13<>"",V$3>=$B13,V$3<=$C13),"■","") | W13: =IF(AND($B13<>"",$C13<>"",W$3>=$B13,W$3<=$C13),"■","") | X13: =IF(AND($B13<>"",$C13<>"",X$3>=$B13,X$3<=$C13),"■","") | Y13: =IF(AND($B13<>"",$C13<>"",Y$3>=$B13,Y$3<=$C13),"■","") | Z13: =IF(AND($B13<>"",$C13<>"",Z$3>=$B13,Z$3<=$C13),"■","") | AA13: =IF(AND($B13<>"",$C13<>"",AA$3>=$B13,AA$3<=$C13),"■","") | AB13: =IF(AND($B13<>"",$C13<>"",AB$3>=$B13,AB$3<=$C13),"■","") | AC13: =IF(AND($B13<>"",$C13<>"",AC$3>=$B13,AC$3<=$C13),"■","") | ... BS13: =IF(AND($B13<>"",$C13<>"",BS$3>=$B13,BS$3<=$C13),"■","")
A14: 10 | B14: 46325 | C14: 46325 | D14: C:block-214 | E14: 第2周 第10天 STAC评估故障机动 | F14: 第2周 第10天 STAC评估故障机动 1. 仅修复可重现技术问题。 2. 检查模块名拼写与实际源码一致。 3. 重跑受影响案例。 4. 无阻塞留出休整。 | G14: 运行STAC原生评估 | H14: 机动与整理 | I14: STAC 论文 官方代码 | J14: 环境和API问题。 | K14: README与源码不一致时有具体修正记录。 | L14: 记录/第2周机动.md。另保存当天的实际命令和执行记录。 | M14: 失败原因可复现，不能将故障当攻击失败统计。 | O14: 未开始 | P14: 0 | V14: =IF(AND($B14<>"",$C14<>"",V$3>=$B14,V$3<=$C14),"■","") | W14: =IF(AND($B14<>"",$C14<>"",W$3>=$B14,W$3<=$C14),"■","") | X14: =IF(AND($B14<>"",$C14<>"",X$3>=$B14,X$3<=$C14),"■","") | Y14: =IF(AND($B14<>"",$C14<>"",Y$3>=$B14,Y$3<=$C14),"■","") | Z14: =IF(AND($B14<>"",$C14<>"",Z$3>=$B14,Z$3<=$C14),"■","") | AA14: =IF(AND($B14<>"",$C14<>"",AA$3>=$B14,AA$3<=$C14),"■","") | AB14: =IF(AND($B14<>"",$C14<>"",AB$3>=$B14,AB$3<=$C14),"■","") | AC14: =IF(AND($B14<>"",$C14<>"",AC$3>=$B14,AC$3<=$C14),"■","") | ... BS14: =IF(AND($B14<>"",$C14<>"",BS$3>=$B14,BS$3<=$C14),"■","")
A15: 11 | B15: 46328 | C15: 46328 | D15: C:block-226 | E15: 第3周 第11天 复现STAC工具链生成 | F15: 第3周 第11天 复现STAC工具链生成 1. 按原任务格式准备少量合成目标。 2. 运行候选生成。 3. 保存工具及参数序列。 4. 把无效工具名和缺参数案例另外列出。 | G15: 复现STAC生成和执行链路 | H15: 主要实现 | I15: STAC 论文 官方代码 | J15: 官方第一阶段入口。 | K15: 得到可供验证器运行的候选链文件。 | L15: results/stac/候选链/。另保存当天的实际命令和执行记录。 | M15: 实际生成过新候选，不只加载作者缓存。 | O15: 未开始 | P15: 0 | V15: =IF(AND($B15<>"",$C15<>"",V$3>=$B15,V$3<=$C15),"■","") | W15: =IF(AND($B15<>"",$C15<>"",W$3>=$B15,W$3<=$C15),"■","") | X15: =IF(AND($B15<>"",$C15<>"",X$3>=$B15,X$3<=$C15),"■","") | Y15: =IF(AND($B15<>"",$C15<>"",Y$3>=$B15,Y$3<=$C15),"■","") | Z15: =IF(AND($B15<>"",$C15<>"",Z$3>=$B15,Z$3<=$C15),"■","") | AA15: =IF(AND($B15<>"",$C15<>"",AA$3>=$B15,AA$3<=$C15),"■","") | AB15: =IF(AND($B15<>"",$C15<>"",AB$3>=$B15,AB$3<=$C15),"■","") | AC15: =IF(AND($B15<>"",$C15<>"",AC$3>=$B15,AC$3<=$C15),"■","") | ... BS15: =IF(AND($B15<>"",$C15<>"",BS$3>=$B15,BS$3<=$C15),"■","")
A16: 12 | B16: 46329 | C16: 46329 | D16: C:block-238 | E16: 第3周 第12天 复现STAC环境内验证 | F16: 第3周 第12天 复现STAC环境内验证 1. 重置每个候选的环境。 2. 按工具链执行。 3. 保存每步结果和失败位置。 4. 将不可执行链排除但保留分母。 | G16: 复现STAC生成和执行链路 | H16: 主要实现 | I16: STAC 论文 官方代码 | J16: 新候选链和原生环境。 | K16: 一条链在第三个工具缺参数处失败。 | L16: results/stac/验证记录/。另保存当天的实际命令和执行记录。 | M16: 所有候选都有去向，验证通过需有实际执行依据。 | O16: 未开始 | P16: 0 | V16: =IF(AND($B16<>"",$C16<>"",V$3>=$B16,V$3<=$C16),"■","") | W16: =IF(AND($B16<>"",$C16<>"",W$3>=$B16,W$3<=$C16),"■","") | X16: =IF(AND($B16<>"",$C16<>"",X$3>=$B16,X$3<=$C16),"■","") | Y16: =IF(AND($B16<>"",$C16<>"",Y$3>=$B16,Y$3<=$C16),"■","") | Z16: =IF(AND($B16<>"",$C16<>"",Z$3>=$B16,Z$3<=$C16),"■","") | AA16: =IF(AND($B16<>"",$C16<>"",AA$3>=$B16,AA$3<=$C16),"■","") | AB16: =IF(AND($B16<>"",$C16<>"",AB$3>=$B16,AB$3<=$C16),"■","") | AC16: =IF(AND($B16<>"",$C16<>"",AC$3>=$B16,AC$3<=$C16),"■","") | ... BS16: =IF(AND($B16<>"",$C16<>"",BS$3>=$B16,BS$3<=$C16),"■","")
... A54: 50 | B54: 46381 | C54: 46381 | D54: C:block-694 | E54: 第10周 第50天 完成十周独立交付 | F54: 第10周 第50天 完成十周独立交付 1. 封存可运行包。 2. 附每种方法的实现层级。 3. 列整体接入后需执行的公平比较。 4. 结束个人复现阶段。 | G54: 编写四方法报告并独立交付 | H54: 机动与整理 | I54: On Over fitting in Model Selection and Subsequent Selection Bias in Performance Evaluation | J54: 四方法代码 文档 运行和限制清单。 | K54: 四方法交付可供后续统一调用与比较。 | L54: release/四方法最终清单.md。另保存当天的实际命令和执行记录。 | M54: 完整与部分复现如实区分，不以个人复现结束代替整体研究已完成。 | O54: 未开始 | P54: 0 | V54: =IF(AND($B54<>"",$C54<>"",V$3>=$B54,V$3<=$C54),"■","") | W54: =IF(AND($B54<>"",$C54<>"",W$3>=$B54,W$3<=$C54),"■","") | X54: =IF(AND($B54<>"",$C54<>"",X$3>=$B54,X$3<=$C54),"■","") | Y54: =IF(AND($B54<>"",$C54<>"",Y$3>=$B54,Y$3<=$C54),"■","") | Z54: =IF(AND($B54<>"",$C54<>"",Z$3>=$B54,Z$3<=$C54),"■","") | AA54: =IF(AND($B54<>"",$C54<>"",AA$3>=$B54,AA$3<=$C54),"■","") | AB54: =IF(AND($B54<>"",$C54<>"",AB$3>=$B54,AB$3<=$C54),"■","") | AC54: =IF(AND($B54<>"",$C54<>"",AC$3>=$B54,AC$3<=$C54),"■","") | ... BS54: =IF(AND($B54<>"",$C54<>"",BS$3>=$B54,BS$3<=$C54),"■","") -> ■

Sheet 总览甘特图
A1: OAPT 三人研究方案总览甘特图
A2: 每一行按负责人和工作日编号直接引用对应人员分表的同一行；A2 即工作 A 的第 2 个工作日任务。
A3: 角色颜色 | B3: A—攻击样本生成 | C3: B—测试平台 | D3: C—基线复现
O4: 46314 | P4: 46315 | Q4: 46316 | R4: 46317 | S4: 46318 | T4: 46321 | U4: 46322 | V4: 46323 | W4: 46324 | X4: 46325 | Y4: 46328 | Z4: 46329 | AA4: 46330 | AB4: 46331 | AC4: 46332 | AD4: 46335 | AE4: 46336 | AF4: 46337 | AG4: 46338 | AH4: 46339 | AI4: 46342 | AJ4: 46343 | AK4: 46344 | AL4: 46345 | AM4: 46346 | AN4: 46349 | AO4: 46350 | AP4: 46351 | AQ4: 46352 | AR4: 46353 | AS4: 46356 | AT4: 46357 | AU4: 46358 | AV4: 46359 | AW4: 46360 | AX4: 46363 | AY4: 46364 | AZ4: 46365 | BA4: 46366 | BB4: 46367 | BC4: 46370 | BD4: 46371 | BE4: 46372 | BF4: 46373 | BG4: 46374 | BH4: 46377 | BI4: 46378 | BJ4: 46379 | BK4: 46380 | BL4: 46381
A5: 负责人 | B5: 工作日编号 | C5: 计划开始日期 | D5: 计划结束日期 | E5: 来源块 | F5: 原文日标题 | G5: 任务名称/当天操作 | H5: 本周目标 | I5: 任务类型 | J5: 状态 | K5: 完成度 | L5: 交付/保存位置 | M5: 证据/阻塞 | N5: 备注 | O5: D1 | P5: D2 | Q5: D3 | R5: D4 | S5: D5 | T5: D6 | U5: D7 | V5: D8 | W5: D9 | X5: D10 | Y5: D11 | Z5: D12 | AA5: D13 | AB5: D14 | AC5: D15 | AD5: D16 | AE5: D17 | AF5: D18 | AG5: D19 | AH5: D20 | AI5: D21 | AJ5: D22 | AK5: D23 | AL5: D24 | AM5: D25 | AN5: D26 | AO5: D27 | AP5: D28 | AQ5: D29 | AR5: D30 | AS5: D31 | AT5: D32 | AU5: D33 | AV5: D34 | AW5: D35 | AX5: D36 | AY5: D37 | AZ5: D38 | BA5: D39 | BB5: D40 | BC5: D41 | BD5: D42 | BE5: D43 | BF5: D44 | BG5: D45 | BH5: D46 | BI5: D47 | BJ5: D48 | BK5: D49 | BL5: D50
A6: ="A" -> A | B6: =A_核心算法!A5 -> 1 | C6: =A_核心算法!B5 -> 46314 | D6: =A_核心算法!C5 -> 46314 | E6: =A_核心算法!D5 -> A:block-116 | F6: =A_核心算法!E5 -> 第1周 第1天 明确这个算法到底做什么 | G6: =A_核心算法!F5 -> 第1周 第1天 明确这个算法到底做什么 1. 写出合法任务、测试目标、输入位置和允许观察四栏。 2. 用虚构维修通知举例说明外部文本不能代替用户授权。 3. 把算法拆成读轨迹、画步骤、换场景、逐步生成四段。 4. 写一页从原始对话到测试记录的流程说明。 | H6: =A_核心算法!G5 -> 明确问题并建立微型执行器 | I6: =A_核心算法!H5 -> 算法研究 | J6: =A_核心算法!O5 -> 未开始 | K6: =A_核心算法!P5 -> 0 | L6: =A_核心算法!S5 | M6: =A_核心算法!T5 | N6: =A_核心算法!U5 | O6: =IF(AND($C6<>"",$D6<>"",O$4>=$C6,O$4<=$D6),"■","") -> ■ | P6: =IF(AND($C6<>"",$D6<>"",P$4>=$C6,P$4<=$D6),"■","") | Q6: =IF(AND($C6<>"",$D6<>"",Q$4>=$C6,Q$4<=$D6),"■","") | R6: =IF(AND($C6<>"",$D6<>"",R$4>=$C6,R$4<=$D6),"■","") | S6: =IF(AND($C6<>"",$D6<>"",S$4>=$C6,S$4<=$D6),"■","") | T6: =IF(AND($C6<>"",$D6<>"",T$4>=$C6,T$4<=$D6),"■","") | U6: =IF(AND($C6<>"",$D6<>"",U$4>=$C6,U$4<=$D6),"■","") | V6: =IF(AND($C6<>"",$D6<>"",V$4>=$C6,V$4<=$D6),"■","") | ... BL6: =IF(AND($C6<>"",$D6<>"",BL$4>=$C6,BL$4<=$D6),"■","")
A7: ="A" -> A | B7: =A_核心算法!A6 -> 2 | C7: =A_核心算法!B6 -> 46315 | D7: =A_核心算法!C6 -> 46315 | E7: =A_核心算法!D6 -> A:block-128 | F7: =A_核心算法!E6 -> 第1周 第2天 独立建好开发环境 | G7: =A_核心算法!F6 -> 第1周 第2天 独立建好开发环境 1. 新建算法目录及data、src、tests、results四个子目录。 2. 安装JSON校验和测试库并保存版本。 3. 写只返回固定文本的模型替身。 4. 运行一个读取样例并写结果的小程序。 | H7: =A_核心算法!G6 -> 明确问题并建立微型执行器 | I7: =A_核心算法!H6 -> 算法研究 | J7: =A_核心算法!O6 -> 未开始 | K7: =A_核心算法!P6 -> 0 | L7: =A_核心算法!S6 | M7: =A_核心算法!T6 | N7: =A_核心算法!U6 | O7: =IF(AND($C7<>"",$D7<>"",O$4>=$C7,O$4<=$D7),"■","") | P7: =IF(AND($C7<>"",$D7<>"",P$4>=$C7,P$4<=$D7),"■","") -> ■ | Q7: =IF(AND($C7<>"",$D7<>"",Q$4>=$C7,Q$4<=$D7),"■","") | R7: =IF(AND($C7<>"",$D7<>"",R$4>=$C7,R$4<=$D7),"■","") | S7: =IF(AND($C7<>"",$D7<>"",S$4>=$C7,S$4<=$D7),"■","") | T7: =IF(AND($C7<>"",$D7<>"",T$4>=$C7,T$4<=$D7),"■","") | U7: =IF(AND($C7<>"",$D7<>"",U$4>=$C7,U$4<=$D7),"■","") | V7: =IF(AND($C7<>"",$D7<>"",V$4>=$C7,V$4<=$D7),"■","") | ... BL7: =IF(AND($C7<>"",$D7<>"",BL$4>=$C7,BL$4<=$D7),"■","")
A8: ="A" -> A | B8: =A_核心算法!A7 -> 3 | C8: =A_核心算法!B7 -> 46316 | D8: =A_核心算法!C7 -> 46316 | E8: =A_核心算法!D7 -> A:block-140 | F8: =A_核心算法!E7 -> 第1周 第3天 写清输入文件长什么样 | G8: =A_核心算法!F7 -> 第1周 第3天 写清输入文件长什么样 1. 给任务、轮次、消息和工具事件设置独立编号。 2. 保存说话人、原文和缺失原因。 3. 把工具请求和真正执行分两条记录。 4. 制作正常、缺字段和编号重复三个文件。 | H8: =A_核心算法!G7 -> 明确问题并建立微型执行器 | I8: =A_核心算法!H7 -> 算法研究 | J8: =A_核心算法!O7 -> 未开始 | K8: =A_核心算法!P7 -> 0 | L8: =A_核心算法!S7 | M8: =A_核心算法!T7 | N8: =A_核心算法!U7 | O8: =IF(AND($C8<>"",$D8<>"",O$4>=$C8,O$4<=$D8),"■","") | P8: =IF(AND($C8<>"",$D8<>"",P$4>=$C8,P$4<=$D8),"■","") | Q8: =IF(AND($C8<>"",$D8<>"",Q$4>=$C8,Q$4<=$D8),"■","") -> ■ | R8: =IF(AND($C8<>"",$D8<>"",R$4>=$C8,R$4<=$D8),"■","") | S8: =IF(AND($C8<>"",$D8<>"",S$4>=$C8,S$4<=$D8),"■","") | T8: =IF(AND($C8<>"",$D8<>"",T$4>=$C8,T$4<=$D8),"■","") | U8: =IF(AND($C8<>"",$D8<>"",U$4>=$C8,U$4<=$D8),"■","") | V8: =IF(AND($C8<>"",$D8<>"",V$4>=$C8,V$4<=$D8),"■","") | ... BL8: =IF(AND($C8<>"",$D8<>"",BL$4>=$C8,BL$4<=$D8),"■","")
A9: ="A" -> A | B9: =A_核心算法!A8 -> 4 | C9: =A_核心算法!B8 -> 46317 | D9: =A_核心算法!C8 -> 46317 | E9: =A_核心算法!D8 -> A:block-152 | F9: =A_核心算法!E8 -> 第1周 第4天 做一个不用等待平台的微型执行器 | G9: =A_核心算法!F8 -> 第1周 第4天 做一个不用等待平台的微型执行器 1. 在内存中放一封通知、一份文件和一个预约。 2. 写读取通知、读取文件、修改预约、查看结果四个函数。 3. 所有函数只读写本地字典。 4. 每次调用都输出请求、是否执行和修改前后内容。 | H9: =A_核心算法!G8 -> 明确问题并建立微型执行器 | I9: =A_核心算法!H8 -> 算法研究 | J9: =A_核心算法!O8 -> 未开始 | K9: =A_核心算法!P8 -> 0 | L9: =A_核心算法!S8 | M9: =A_核心算法!T8 | N9: =A_核心算法!U8 | O9: =IF(AND($C9<>"",$D9<>"",O$4>=$C9,O$4<=$D9),"■","") | P9: =IF(AND($C9<>"",$D9<>"",P$4>=$C9,P$4<=$D9),"■","") | Q9: =IF(AND($C9<>"",$D9<>"",Q$4>=$C9,Q$4<=$D9),"■","") | R9: =IF(AND($C9<>"",$D9<>"",R$4>=$C9,R$4<=$D9),"■","") -> ■ | S9: =IF(AND($C9<>"",$D9<>"",S$4>=$C9,S$4<=$D9),"■","") | T9: =IF(AND($C9<>"",$D9<>"",T$4>=$C9,T$4<=$D9),"■","") | U9: =IF(AND($C9<>"",$D9<>"",U$4>=$C9,U$4<=$D9),"■","") | V9: =IF(AND($C9<>"",$D9<>"",V$4>=$C9,V$4<=$D9),"■","") | ... BL9: =IF(AND($C9<>"",$D9<>"",BL$4>=$C9,BL$4<=$D9),"■","")
A10: ="A" -> A | B10: =A_核心算法!A9 -> 5 | C10: =A_核心算法!B9 -> 46318 | D10: =A_核心算法!C9 -> 46318 | E10: =A_核心算法!D9 -> A:block-164 | F10: =A_核心算法!E9 -> 第1周 第5天 检查第一周是否真正可运行 | G10: =A_核心算法!F9 -> 第1周 第5天 检查第一周是否真正可运行 1. 从新目录复制项目并重新安装。 2. 逐个运行读取、修改和重置示例。 3. 故意删除一个字段观察报错。 4. 记录还不会做的操作并补最小示例。 | H10: =A_核心算法!G9 -> 明确问题并建立微型执行器 | I10: =A_核心算法!H9 -> 算法研究 | J10: =A_核心算法!O9 -> 未开始 | K10: =A_核心算法!P9 -> 0 | L10: =A_核心算法!S9 | M10: =A_核心算法!T9 | N10: =A_核心算法!U9 | O10: =IF(AND($C10<>"",$D10<>"",O$4>=$C10,O$4<=$D10),"■","") | P10: =IF(AND($C10<>"",$D10<>"",P$4>=$C10,P$4<=$D10),"■","") | Q10: =IF(AND($C10<>"",$D10<>"",Q$4>=$C10,Q$4<=$D10),"■","") | R10: =IF(AND($C10<>"",$D10<>"",R$4>=$C10,R$4<=$D10),"■","") | S10: =IF(AND($C10<>"",$D10<>"",S$4>=$C10,S$4<=$D10),"■","") -> ■ | T10: =IF(AND($C10<>"",$D10<>"",T$4>=$C10,T$4<=$D10),"■","") | U10: =IF(AND($C10<>"",$D10<>"",U$4>=$C10,U$4<=$D10),"■","") | V10: =IF(AND($C10<>"",$D10<>"",V$4>=$C10,V$4<=$D10),"■","") | ... BL10: =IF(AND($C10<>"",$D10<>"",BL$4>=$C10,BL$4<=$D10),"■","")
A11: ="A" -> A | B11: =A_核心算法!A10 -> 6 | C11: =A_核心算法!B10 -> 46321 | D11: =A_核心算法!C10 -> 46321 | E11: =A_核心算法!D10 -> A:block-176 | F11: =A_核心算法!E10 -> 第2周 第6天 收集历史多轮轨迹 | G11: =A_核心算法!F10 -> 第2周 第6天 收集历史多轮轨迹 1. 建立来源、版本、许可、实际下载文件四列表。 2. 先查看每个来源10条。 3. 标记是否含多轮回复及工具结果。 4. 继续整理至200条候选并保留排除原因。 | H11: =A_核心算法!G10 -> 收集真实轨迹并建立个人标注说明 | I11: =A_核心算法!H10 -> 算法研究 | J11: =A_核心算法!O10 -> 未开始 | K11: =A_核心算法!P10 -> 0 | L11: =A_核心算法!S10 | M11: =A_核心算法!T10 | N11: =A_核心算法!U10 | O11: =IF(AND($C11<>"",$D11<>"",O$4>=$C11,O$4<=$D11),"■","") | P11: =IF(AND($C11<>"",$D11<>"",P$4>=$C11,P$4<=$D11),"■","") | Q11: =IF(AND($C11<>"",$D11<>"",Q$4>=$C11,Q$4<=$D11),"■","") | R11: =IF(AND($C11<>"",$D11<>"",R$4>=$C11,R$4<=$D11),"■","") | S11: =IF(AND($C11<>"",$D11<>"",S$4>=$C11,S$4<=$D11),"■","") | T11: =IF(AND($C11<>"",$D11<>"",T$4>=$C11,T$4<=$D11),"■","") -> ■ | U11: =IF(AND($C11<>"",$D11<>"",U$4>=$C11,U$4<=$D11),"■","") | V11: =IF(AND($C11<>"",$D11<>"",V$4>=$C11,V$4<=$D11),"■","") | ... BL11: =IF(AND($C11<>"",$D11<>"",BL$4>=$C11,BL$4<=$D11),"■","")
A12: ="A" -> A | B12: =A_核心算法!A11 -> 7 | C12: =A_核心算法!B11 -> 46322 | D12: =A_核心算法!C11 -> 46322 | E12: =A_核心算法!D11 -> A:block-188 | F12: =A_核心算法!E11 -> 第2周 第7天 筛出真正能够使用的轨迹 | G12: =A_核心算法!F11 -> 第2周 第7天 筛出真正能够使用的轨迹 1. 排除重复、只有单句和缺少回复的记录。 2. 按原案例及改写变体设置同一组号。 3. 统计候选到可建图的各步数量。 4. 把不完整但仍有价值的记录另存。 | H12: =A_核心算法!G11 -> 收集真实轨迹并建立个人标注说明 | I12: =A_核心算法!H11 -> 算法研究 | J12: =A_核心算法!O11 -> 未开始 | K12: =A_核心算法!P11 -> 0 | L12: =A_核心算法!S11 | M12: =A_核心算法!T11 | N12: =A_核心算法!U11 | O12: =IF(AND($C12<>"",$D12<>"",O$4>=$C12,O$4<=$D12),"■","") | P12: =IF(AND($C12<>"",$D12<>"",P$4>=$C12,P$4<=$D12),"■","") | Q12: =IF(AND($C12<>"",$D12<>"",Q$4>=$C12,Q$4<=$D12),"■","") | R12: =IF(AND($C12<>"",$D12<>"",R$4>=$C12,R$4<=$D12),"■","") | S12: =IF(AND($C12<>"",$D12<>"",S$4>=$C12,S$4<=$D12),"■","") | T12: =IF(AND($C12<>"",$D12<>"",T$4>=$C12,T$4<=$D12),"■","") | U12: =IF(AND($C12<>"",$D12<>"",U$4>=$C12,U$4<=$D12),"■","") -> ■ | V12: =IF(AND($C12<>"",$D12<>"",V$4>=$C12,V$4<=$D12),"■","") | ... BL12: =IF(AND($C12<>"",$D12<>"",BL$4>=$C12,BL$4<=$D12),"■","")
A13: ="A" -> A | B13: =A_核心算法!A12 -> 8 | C13: =A_核心算法!B12 -> 46323 | D13: =A_核心算法!C12 -> 46323 | E13: =A_核心算法!D12 -> A:block-200 | F13: =A_核心算法!E12 -> 第2周 第8天 自己先画十条示范步骤图 | G13: =A_核心算法!F12 -> 第2周 第8天 自己先画十条示范步骤图 1. 逐轮写这一轮发生了什么。 2. 只在目标或工具效果改变时另起一步。 3. 把每一步对应原消息编号。 4. 分别画先后关系和有证据的依赖关系。 | H13: =A_核心算法!G12 -> 收集真实轨迹并建立个人标注说明 | I13: =A_核心算法!H12 -> 算法研究 | J13: =A_核心算法!O12 -> 未开始 | K13: =A_核心算法!P12 -> 0 | L13: =A_核心算法!S12 | M13: =A_核心算法!T12 | N13: =A_核心算法!U12 | O13: =IF(AND($C13<>"",$D13<>"",O$4>=$C13,O$4<=$D13),"■","") | P13: =IF(AND($C13<>"",$D13<>"",P$4>=$C13,P$4<=$D13),"■","") | Q13: =IF(AND($C13<>"",$D13<>"",Q$4>=$C13,Q$4<=$D13),"■","") | R13: =IF(AND($C13<>"",$D13<>"",R$4>=$C13,R$4<=$D13),"■","") | S13: =IF(AND($C13<>"",$D13<>"",S$4>=$C13,S$4<=$D13),"■","") | T13: =IF(AND($C13<>"",$D13<>"",T$4>=$C13,T$4<=$D13),"■","") | U13: =IF(AND($C13<>"",$D13<>"",U$4>=$C13,U$4<=$D13),"■","") | V13: =IF(AND($C13<>"",$D13<>"",V$4>=$C13,V$4<=$D13),"■","") -> ■ | ... BL13: =IF(AND($C13<>"",$D13<>"",BL$4>=$C13,BL$4<=$D13),"■","")
A14: ="A" -> A | B14: =A_核心算法!A13 -> 9 | C14: =A_核心算法!B13 -> 46324 | D14: =A_核心算法!C13 -> 46324 | E14: =A_核心算法!D13 -> A:block-212 | F14: =A_核心算法!E13 -> 第2周 第9天 编写容易照着用的标注说明 | G14: =A_核心算法!F13 -> 第2周 第9天 编写容易照着用的标注说明 1. 解释什么时候划分新步骤。 2. 给先后、依赖、未知各写两个例子。 3. 写缺少工具结果时如何处理。 4. 隔一天重新标五条并记录自己的不一致。 | H14: =A_核心算法!G13 -> 收集真实轨迹并建立个人标注说明 | I14: =A_核心算法!H13 -> 算法研究 | J14: =A_核心算法!O13 -> 未开始 | K14: =A_核心算法!P13 -> 0 | L14: =A_核心算法!S13 | M14: =A_核心算法!T13 | N14: =A_核心算法!U13 | O14: =IF(AND($C14<>"",$D14<>"",O$4>=$C14,O$4<=$D14),"■","") | P14: =IF(AND($C14<>"",$D14<>"",P$4>=$C14,P$4<=$D14),"■","") | Q14: =IF(AND($C14<>"",$D14<>"",Q$4>=$C14,Q$4<=$D14),"■","") | R14: =IF(AND($C14<>"",$D14<>"",R$4>=$C14,R$4<=$D14),"■","") | S14: =IF(AND($C14<>"",$D14<>"",S$4>=$C14,S$4<=$D14),"■","") | T14: =IF(AND($C14<>"",$D14<>"",T$4>=$C14,T$4<=$D14),"■","") | U14: =IF(AND($C14<>"",$D14<>"",U$4>=$C14,U$4<=$D14),"■","") | V14: =IF(AND($C14<>"",$D14<>"",V$4>=$C14,V$4<=$D14),"■","") | ... BL14: =IF(AND($C14<>"",$D14<>"",BL$4>=$C14,BL$4<=$D14),"■","")
A15: ="A" -> A | B15: =A_核心算法!A14 -> 10 | C15: =A_核心算法!B14 -> 46325 | D15: =A_核心算法!C14 -> 46325 | E15: =A_核心算法!D14 -> A:block-224 | F15: =A_核心算法!E14 -> 第2周 第10天 冻结可用数据和开发样本 | G15: =A_核心算法!F14 -> 第2周 第10天 冻结可用数据和开发样本 1. 把同一来源组整体放入开发或留出文件。 2. 先选20条开发用轨迹。 3. 保存其余留出数据不用于改提示。 4. 记录实际数量不足时能研究什么。 | H15: =A_核心算法!G14 -> 收集真实轨迹并建立个人标注说明 | I15: =A_核心算法!H14 -> 算法研究 | J15: =A_核心算法!O14 -> 未开始 | K15: =A_核心算法!P14 -> 0 | L15: =A_核心算法!S14 | M15: =A_核心算法!T14 | N15: =A_核心算法!U14 | O15: =IF(AND($C15<>"",$D15<>"",O$4>=$C15,O$4<=$D15),"■","") | P15: =IF(AND($C15<>"",$D15<>"",P$4>=$C15,P$4<=$D15),"■","") | Q15: =IF(AND($C15<>"",$D15<>"",Q$4>=$C15,Q$4<=$D15),"■","") | R15: =IF(AND($C15<>"",$D15<>"",R$4>=$C15,R$4<=$D15),"■","") | S15: =IF(AND($C15<>"",$D15<>"",S$4>=$C15,S$4<=$D15),"■","") | T15: =IF(AND($C15<>"",$D15<>"",T$4>=$C15,T$4<=$D15),"■","") | U15: =IF(AND($C15<>"",$D15<>"",U$4>=$C15,U$4<=$D15),"■","") | V15: =IF(AND($C15<>"",$D15<>"",V$4>=$C15,V$4<=$D15),"■","") | ... BL15: =IF(AND($C15<>"",$D15<>"",BL$4>=$C15,BL$4<=$D15),"■","")
A16: ="A" -> A | B16: =A_核心算法!A15 -> 11 | C16: =A_核心算法!B15 -> 46328 | D16: =A_核心算法!C15 -> 46328 | E16: =A_核心算法!D15 -> A:block-236 | F16: =A_核心算法!E15 -> 第3周 第11天 写按轮次整理对话的程序 | G16: =A_核心算法!F15 -> 第3周 第11天 写按轮次整理对话的程序 1. 逐条读取消息。 2. 保持原始顺序和编号。 3. 把工具调用、返回、状态修改识别成不同事件。 4. 输出便于查看的逐轮表。 | H16: =A_核心算法!G15 -> 实现步骤抽取与证据检查 | I16: =A_核心算法!H15 -> 算法研究 | J16: =A_核心算法!O15 -> 未开始 | K16: =A_核心算法!P15 -> 0 | L16: =A_核心算法!S15 | M16: =A_核心算法!T15 | N16: =A_核心算法!U15 | O16: =IF(AND($C16<>"",$D16<>"",O$4>=$C16,O$4<=$D16),"■","") | P16: =IF(AND($C16<>"",$D16<>"",P$4>=$C16,P$4<=$D16),"■","") | Q16: =IF(AND($C16<>"",$D16<>"",Q$4>=$C16,Q$4<=$D16),"■","") | R16: =IF(AND($C16<>"",$D16<>"",R$4>=$C16,R$4<=$D16),"■","") | S16: =IF(AND($C16<>"",$D16<>"",S$4>=$C16,S$4<=$D16),"■","") | T16: =IF(AND($C16<>"",$D16<>"",T$4>=$C16,T$4<=$D16),"■","") | U16: =IF(AND($C16<>"",$D16<>"",U$4>=$C16,U$4<=$D16),"■","") | V16: =IF(AND($C16<>"",$D16<>"",V$4>=$C16,V$4<=$D16),"■","") | ... BL16: =IF(AND($C16<>"",$D16<>"",BL$4>=$C16,BL$4<=$D16),"■","")
A17: ="A" -> A | B17: =A_核心算法!A16 -> 12 | C17: =A_核心算法!B16 -> 46329 | D17: =A_核心算法!C16 -> 46329 | E17: =A_核心算法!D16 -> A:block-248 | F17: =A_核心算法!E16 -> 第3周 第12天 做最简单的规则抽取方法 | G17: =A_核心算法!F16 -> 第3周 第12天 做最简单的规则抽取方法 1. 遇到工具请求建立候选步骤。 2. 把随后同编号返回绑定到该步。 3. 没有返回就标缺失。 4. 把每步的动作和对象输出成表。 | H17: =A_核心算法!G16 -> 实现步骤抽取与证据检查 | I17: =A_核心算法!H16 -> 算法研究 | J17: =A_核心算法!O16 -> 未开始 | K17: =A_核心算法!P16 -> 0 | L17: =A_核心算法!S16 | M17: =A_核心算法!T16 | N17: =A_核心算法!U16 | O17: =IF(AND($C17<>"",$D17<>"",O$4>=$C17,O$4<=$D17),"■","") | P17: =IF(AND($C17<>"",$D17<>"",P$4>=$C17,P$4<=$D17),"■","") | Q17: =IF(AND($C17<>"",$D17<>"",Q$4>=$C17,Q$4<=$D17),"■","") | R17: =IF(AND($C17<>"",$D17<>"",R$4>=$C17,R$4<=$D17),"■","") | S17: =IF(AND($C17<>"",$D17<>"",S$4>=$C17,S$4<=$D17),"■","") | T17: =IF(AND($C17<>"",$D17<>"",T$4>=$C17,T$4<=$D17),"■","") | U17: =IF(AND($C17<>"",$D17<>"",U$4>=$C17,U$4<=$D17),"■","") | V17: =IF(AND($C17<>"",$D17<>"",V$4>=$C17,V$4<=$D17),"■","") | ... BL17: =IF(AND($C17<>"",$D17<>"",BL$4>=$C17,BL$4<=$D17),"■","")
... A55: ="A" -> A | B55: =A_核心算法!A54 -> 50 | C55: =A_核心算法!B54 -> 46381 | D55: =A_核心算法!C54 -> 46381 | E55: =A_核心算法!D54 -> A:block-704 | F55: =A_核心算法!E54 -> 第10周 第50天 完成十周独立工作 | G55: =A_核心算法!F54 -> 第10周 第50天 完成十周独立工作 1. 核对50日实际记录。 2. 导出最终依赖和版本。 3. 列尚需项目负责人整合的项目。 4. 封存交付目录并结束独立开发。 | H55: =A_核心算法!G54 -> 补齐回归测试并独立交付 | I55: =A_核心算法!H54 -> 算法研究 | J55: =A_核心算法!O54 -> 未开始 | K55: =A_核心算法!P54 -> 0 | L55: =A_核心算法!S54 | M55: =A_核心算法!T54 | N55: =A_核心算法!U54 | O55: =IF(AND($C55<>"",$D55<>"",O$4>=$C55,O$4<=$D55),"■","") | P55: =IF(AND($C55<>"",$D55<>"",P$4>=$C55,P$4<=$D55),"■","") | Q55: =IF(AND($C55<>"",$D55<>"",Q$4>=$C55,Q$4<=$D55),"■","") | R55: =IF(AND($C55<>"",$D55<>"",R$4>=$C55,R$4<=$D55),"■","") | S55: =IF(AND($C55<>"",$D55<>"",S$4>=$C55,S$4<=$D55),"■","") | T55: =IF(AND($C55<>"",$D55<>"",T$4>=$C55,T$4<=$D55),"■","") | U55: =IF(AND($C55<>"",$D55<>"",U$4>=$C55,U$4<=$D55),"■","") | V55: =IF(AND($C55<>"",$D55<>"",V$4>=$C55,V$4<=$D55),"■","") | ... BL55: =IF(AND($C55<>"",$D55<>"",BL$4>=$C55,BL$4<=$D55),"■","") -> ■
A56: ="B" -> B | B56: =B_测试平台!A5 -> 1 | C56: =B_测试平台!B5 -> 46314 | D56: =B_测试平台!C5 -> 46314 | E56: =B_测试平台!D5 -> B:block-91 | F56: =B_测试平台!E5 -> 第1周 第1天 先明确平台要模拟哪些事情 | G56: =B_测试平台!F5 -> 第1周 第1天 先明确平台要模拟哪些事情 1. 列邮件、文件、日程、车载四个必做场景。 2. 为每个场景写合法用户任务。 3. 把读取和修改分成两类。 4. 写平台只操作合成数据的范围说明。 | H56: =B_测试平台!G5 -> 安装现有基础并建立独立入口 | I56: =B_测试平台!H5 -> 主要实现 | J56: =B_测试平台!O5 -> 未开始 | K56: =B_测试平台!P5 -> 0 | L56: =B_测试平台!S5 | M56: =B_测试平台!T5 | N56: =B_测试平台!U5 | O56: =IF(AND($C56<>"",$D56<>"",O$4>=$C56,O$4<=$D56),"■","") -> ■ | P56: =IF(AND($C56<>"",$D56<>"",P$4>=$C56,P$4<=$D56),"■","") | Q56: =IF(AND($C56<>"",$D56<>"",Q$4>=$C56,Q$4<=$D56),"■","") | R56: =IF(AND($C56<>"",$D56<>"",R$4>=$C56,R$4<=$D56),"■","") | S56: =IF(AND($C56<>"",$D56<>"",S$4>=$C56,S$4<=$D56),"■","") | T56: =IF(AND($C56<>"",$D56<>"",T$4>=$C56,T$4<=$D56),"■","") | U56: =IF(AND($C56<>"",$D56<>"",U$4>=$C56,U$4<=$D56),"■","") | V56: =IF(AND($C56<>"",$D56<>"",V$4>=$C56,V$4<=$D56),"■","") | ... BL56: =IF(AND($C56<>"",$D56<>"",BL$4>=$C56,BL$4<=$D56),"■","")
A57: ="B" -> B | B57: =B_测试平台!A6 -> 2 | C57: =B_测试平台!B6 -> 46315 | D57: =B_测试平台!C6 -> 46315 | E57: =B_测试平台!D6 -> B:block-103 | F57: =B_测试平台!E6 -> 第1周 第2天 安装现成环境并运行最小例子 | G57: =B_测试平台!F6 -> 第1周 第2天 安装现成环境并运行最小例子 1. 按官方说明安装独立环境。 2. 运行工具注册和依赖检查。 3. 先用固定回复代替真实模型。 4. 保存实际安装命令和版本。 | H57: =B_测试平台!G6 -> 安装现有基础并建立独立入口 | I57: =B_测试平台!H6 -> 主要实现 | J57: =B_测试平台!O6 -> 未开始 | K57: =B_测试平台!P6 -> 0 | L57: =B_测试平台!S6 | M57: =B_测试平台!T6 | N57: =B_测试平台!U6 | O57: =IF(AND($C57<>"",$D57<>"",O$4>=$C57,O$4<=$D57),"■","") | P57: =IF(AND($C57<>"",$D57<>"",P$4>=$C57,P$4<=$D57),"■","") -> ■ | Q57: =IF(AND($C57<>"",$D57<>"",Q$4>=$C57,Q$4<=$D57),"■","") | R57: =IF(AND($C57<>"",$D57<>"",R$4>=$C57,R$4<=$D57),"■","") | S57: =IF(AND($C57<>"",$D57<>"",S$4>=$C57,S$4<=$D57),"■","") | T57: =IF(AND($C57<>"",$D57<>"",T$4>=$C57,T$4<=$D57),"■","") | U57: =IF(AND($C57<>"",$D57<>"",U$4>=$C57,U$4<=$D57),"■","") | V57: =IF(AND($C57<>"",$D57<>"",V$4>=$C57,V$4<=$D57),"■","") | ... BL57: =IF(AND($C57<>"",$D57<>"",BL$4>=$C57,BL$4<=$D57),"■","")
A58: ="B" -> B | B58: =B_测试平台!A7 -> 3 | C58: =B_测试平台!B7 -> 46316 | D58: =B_测试平台!C7 -> 46316 | E58: =B_测试平台!D7 -> B:block-115 | F58: =B_测试平台!E7 -> 第1周 第3天 设计一个通用运行入口 | G58: =B_测试平台!F7 -> 第1周 第3天 设计一个通用运行入口 1. 规定任务说明、用户身份、初始数据和权限四部分。 2. 写读取任务文件的程序。 3. 把工具调用传给执行函数。 4. 保存每轮输入与输出。 | H58: =B_测试平台!G7 -> 安装现有基础并建立独立入口 | I58: =B_测试平台!H7 -> 主要实现 | J58: =B_测试平台!O7 -> 未开始 | K58: =B_测试平台!P7 -> 0 | L58: =B_测试平台!S7 | M58: =B_测试平台!T7 | N58: =B_测试平台!U7 | O58: =IF(AND($C58<>"",$D58<>"",O$4>=$C58,O$4<=$D58),"■","") | P58: =IF(AND($C58<>"",$D58<>"",P$4>=$C58,P$4<=$D58),"■","") | Q58: =IF(AND($C58<>"",$D58<>"",Q$4>=$C58,Q$4<=$D58),"■","") -> ■ | R58: =IF(AND($C58<>"",$D58<>"",R$4>=$C58,R$4<=$D58),"■","") | S58: =IF(AND($C58<>"",$D58<>"",S$4>=$C58,S$4<=$D58),"■","") | T58: =IF(AND($C58<>"",$D58<>"",T$4>=$C58,T$4<=$D58),"■","") | U58: =IF(AND($C58<>"",$D58<>"",U$4>=$C58,U$4<=$D58),"■","") | V58: =IF(AND($C58<>"",$D58<>"",V$4>=$C58,V$4<=$D58),"■","") | ... BL58: =IF(AND($C58<>"",$D58<>"",BL$4>=$C58,BL$4<=$D58),"■","")
